[2025-02-28T17:54:20.682+0000] {local_task_job_runner.py:123} INFO - ::group::Pre task execution logs
[2025-02-28T17:54:20.704+0000] {taskinstance.py:2614} INFO - Dependencies all met for dep_context=non-requeueable deps ti=<TaskInstance: ha_etl_process.extract_task scheduled__2025-02-27T00:00:00+00:00 [queued]>
[2025-02-28T17:54:20.714+0000] {taskinstance.py:2614} INFO - Dependencies all met for dep_context=requeueable deps ti=<TaskInstance: ha_etl_process.extract_task scheduled__2025-02-27T00:00:00+00:00 [queued]>
[2025-02-28T17:54:20.715+0000] {taskinstance.py:2867} INFO - Starting attempt 1 of 2
[2025-02-28T17:54:20.737+0000] {taskinstance.py:2890} INFO - Executing <Task(PythonOperator): extract_task> on 2025-02-27 00:00:00+00:00
[2025-02-28T17:54:20.752+0000] {logging_mixin.py:190} WARNING - /home/***/.local/lib/python3.12/site-packages/***/task/task_runner/standard_task_runner.py:70 DeprecationWarning: This process (pid=1112) is multi-threaded, use of fork() may lead to deadlocks in the child.
[2025-02-28T17:54:20.752+0000] {standard_task_runner.py:104} INFO - Running: ['***', 'tasks', 'run', 'ha_etl_process', 'extract_task', 'scheduled__2025-02-27T00:00:00+00:00', '--job-id', '121', '--raw', '--subdir', 'DAGS_FOLDER/ha_etl_process.py', '--cfg-path', '/tmp/tmpmcqu4boe']
[2025-02-28T17:54:20.754+0000] {standard_task_runner.py:72} INFO - Started process 1114 to run task
[2025-02-28T17:54:20.755+0000] {standard_task_runner.py:105} INFO - Job 121: Subtask extract_task
[2025-02-28T17:54:20.837+0000] {task_command.py:467} INFO - Running <TaskInstance: ha_etl_process.extract_task scheduled__2025-02-27T00:00:00+00:00 [running]> on host 151d4861bf1b
[2025-02-28T17:54:20.942+0000] {taskinstance.py:3134} INFO - Exporting env vars: AIRFLOW_CTX_DAG_OWNER='***' AIRFLOW_CTX_DAG_ID='ha_etl_process' AIRFLOW_CTX_TASK_ID='extract_task' AIRFLOW_CTX_EXECUTION_DATE='2025-02-27T00:00:00+00:00' AIRFLOW_CTX_TRY_NUMBER='1' AIRFLOW_CTX_DAG_RUN_ID='scheduled__2025-02-27T00:00:00+00:00'
[2025-02-28T17:54:20.944+0000] {logging_mixin.py:190} INFO - Task instance is in running state
[2025-02-28T17:54:20.945+0000] {logging_mixin.py:190} INFO -  Previous state of the Task instance: queued
[2025-02-28T17:54:20.946+0000] {logging_mixin.py:190} INFO - Current task name:extract_task state:running start_date:2025-02-28 17:54:20.705297+00:00
[2025-02-28T17:54:20.946+0000] {logging_mixin.py:190} INFO - Dag name:ha_etl_process and current dag run status:running
[2025-02-28T17:54:20.947+0000] {taskinstance.py:732} INFO - ::endgroup::
[2025-02-28T17:54:20.948+0000] {logging_mixin.py:190} INFO - üîç Tentando se conectar ao Home Assistant...
[2025-02-28T17:54:20.948+0000] {logging_mixin.py:190} INFO - üì¶ Extraindo hist√≥rico da entidade sensor.abc_consumo_ativo_total...
[2025-02-28T17:54:20.949+0000] {logging_mixin.py:190} INFO - ‚ùå Erro na extra√ß√£o dos dados: type object 'datetime.datetime' has no attribute 'datetime'
[2025-02-28T17:54:20.951+0000] {taskinstance.py:3313} ERROR - Task failed with exception
Traceback (most recent call last):
  File "/home/airflow/.local/lib/python3.12/site-packages/airflow/models/taskinstance.py", line 768, in _execute_task
    result = _execute_callable(context=context, **execute_callable_kwargs)
             ^^^^^^^^^^^^^^^^^^^^^^^^^^^^^^^^^^^^^^^^^^^^^^^^^^^^^^^^^^^^^
  File "/home/airflow/.local/lib/python3.12/site-packages/airflow/models/taskinstance.py", line 734, in _execute_callable
    return ExecutionCallableRunner(
           ^^^^^^^^^^^^^^^^^^^^^^^^
  File "/home/airflow/.local/lib/python3.12/site-packages/airflow/utils/operator_helpers.py", line 252, in run
    return self.func(*args, **kwargs)
           ^^^^^^^^^^^^^^^^^^^^^^^^^^
  File "/home/airflow/.local/lib/python3.12/site-packages/airflow/models/baseoperator.py", line 424, in wrapper
    return func(self, *args, **kwargs)
           ^^^^^^^^^^^^^^^^^^^^^^^^^^^
  File "/home/airflow/.local/lib/python3.12/site-packages/airflow/operators/python.py", line 238, in execute
    return_value = self.execute_callable()
                   ^^^^^^^^^^^^^^^^^^^^^^^
  File "/home/airflow/.local/lib/python3.12/site-packages/airflow/operators/python.py", line 256, in execute_callable
    return runner.run(*self.op_args, **self.op_kwargs)
           ^^^^^^^^^^^^^^^^^^^^^^^^^^^^^^^^^^^^^^^^^^^
  File "/home/airflow/.local/lib/python3.12/site-packages/airflow/utils/operator_helpers.py", line 252, in run
    return self.func(*args, **kwargs)
           ^^^^^^^^^^^^^^^^^^^^^^^^^^
  File "/opt/airflow/dags/ha_etl_process.py", line 132, in extract_data
    history = ha.get_entity_history(entity_consumo_mes)
              ^^^^^^^^^^^^^^^^^^^^^^^^^^^^^^^^^^^^^^^^^
  File "/opt/airflow/dags/ha_etl_process.py", line 46, in get_entity_history
    end_time = datetime.datetime.now(datetime.timezone.utc)
               ^^^^^^^^^^^^^^^^^
AttributeError: type object 'datetime.datetime' has no attribute 'datetime'
[2025-02-28T17:54:20.975+0000] {logging_mixin.py:190} INFO - Task instance in failure state
[2025-02-28T17:54:20.976+0000] {logging_mixin.py:190} INFO - Task start:2025-02-28 17:54:20.705297+00:00 end:2025-02-28 17:54:20.975197+00:00 duration:0.2699
[2025-02-28T17:54:20.977+0000] {logging_mixin.py:190} INFO - Task:<Task(PythonOperator): extract_task> dag:<DAG: ha_etl_process> dagrun:<DagRun ha_etl_process @ 2025-02-27 00:00:00+00:00: scheduled__2025-02-27T00:00:00+00:00, state:running, queued_at: 2025-02-28 17:54:19.144082+00:00. externally triggered: False>
[2025-02-28T17:54:20.977+0000] {logging_mixin.py:190} INFO - Failure caused by type object 'datetime.datetime' has no attribute 'datetime'
[2025-02-28T17:54:20.978+0000] {taskinstance.py:1226} INFO - Marking task as UP_FOR_RETRY. dag_id=ha_etl_process, task_id=extract_task, run_id=scheduled__2025-02-27T00:00:00+00:00, execution_date=20250227T000000, start_date=20250228T175420, end_date=20250228T175420
[2025-02-28T17:54:21.019+0000] {taskinstance.py:341} INFO - ::group::Post task execution logs
[2025-02-28T17:54:21.020+0000] {standard_task_runner.py:124} ERROR - Failed to execute job 121 for task extract_task (type object 'datetime.datetime' has no attribute 'datetime'; 1114)
Traceback (most recent call last):
  File "/home/airflow/.local/lib/python3.12/site-packages/airflow/task/task_runner/standard_task_runner.py", line 117, in _start_by_fork
    ret = args.func(args, dag=self.dag)
          ^^^^^^^^^^^^^^^^^^^^^^^^^^^^^
  File "/home/airflow/.local/lib/python3.12/site-packages/airflow/cli/cli_config.py", line 49, in command
    return func(*args, **kwargs)
           ^^^^^^^^^^^^^^^^^^^^^
  File "/home/airflow/.local/lib/python3.12/site-packages/airflow/utils/cli.py", line 116, in wrapper
    return f(*args, **kwargs)
           ^^^^^^^^^^^^^^^^^^
  File "/home/airflow/.local/lib/python3.12/site-packages/airflow/cli/commands/task_command.py", line 483, in task_run
    task_return_code = _run_task_by_selected_method(args, _dag, ti)
                       ^^^^^^^^^^^^^^^^^^^^^^^^^^^^^^^^^^^^^^^^^^^^
  File "/home/airflow/.local/lib/python3.12/site-packages/airflow/cli/commands/task_command.py", line 256, in _run_task_by_selected_method
    return _run_raw_task(args, ti)
           ^^^^^^^^^^^^^^^^^^^^^^^
  File "/home/airflow/.local/lib/python3.12/site-packages/airflow/cli/commands/task_command.py", line 341, in _run_raw_task
    return ti._run_raw_task(
           ^^^^^^^^^^^^^^^^^
  File "/home/airflow/.local/lib/python3.12/site-packages/airflow/utils/session.py", line 97, in wrapper
    return func(*args, session=session, **kwargs)
           ^^^^^^^^^^^^^^^^^^^^^^^^^^^^^^^^^^^^^^
  File "/home/airflow/.local/lib/python3.12/site-packages/airflow/models/taskinstance.py", line 3006, in _run_raw_task
    return _run_raw_task(
           ^^^^^^^^^^^^^^
  File "/home/airflow/.local/lib/python3.12/site-packages/airflow/models/taskinstance.py", line 274, in _run_raw_task
    TaskInstance._execute_task_with_callbacks(
  File "/home/airflow/.local/lib/python3.12/site-packages/airflow/models/taskinstance.py", line 3161, in _execute_task_with_callbacks
    result = self._execute_task(context, task_orig)
             ^^^^^^^^^^^^^^^^^^^^^^^^^^^^^^^^^^^^^^
  File "/home/airflow/.local/lib/python3.12/site-packages/airflow/models/taskinstance.py", line 3185, in _execute_task
    return _execute_task(self, context, task_orig)
           ^^^^^^^^^^^^^^^^^^^^^^^^^^^^^^^^^^^^^^^
  File "/home/airflow/.local/lib/python3.12/site-packages/airflow/models/taskinstance.py", line 768, in _execute_task
    result = _execute_callable(context=context, **execute_callable_kwargs)
             ^^^^^^^^^^^^^^^^^^^^^^^^^^^^^^^^^^^^^^^^^^^^^^^^^^^^^^^^^^^^^
  File "/home/airflow/.local/lib/python3.12/site-packages/airflow/models/taskinstance.py", line 734, in _execute_callable
    return ExecutionCallableRunner(
           ^^^^^^^^^^^^^^^^^^^^^^^^
  File "/home/airflow/.local/lib/python3.12/site-packages/airflow/utils/operator_helpers.py", line 252, in run
    return self.func(*args, **kwargs)
           ^^^^^^^^^^^^^^^^^^^^^^^^^^
  File "/home/airflow/.local/lib/python3.12/site-packages/airflow/models/baseoperator.py", line 424, in wrapper
    return func(self, *args, **kwargs)
           ^^^^^^^^^^^^^^^^^^^^^^^^^^^
  File "/home/airflow/.local/lib/python3.12/site-packages/airflow/operators/python.py", line 238, in execute
    return_value = self.execute_callable()
                   ^^^^^^^^^^^^^^^^^^^^^^^
  File "/home/airflow/.local/lib/python3.12/site-packages/airflow/operators/python.py", line 256, in execute_callable
    return runner.run(*self.op_args, **self.op_kwargs)
           ^^^^^^^^^^^^^^^^^^^^^^^^^^^^^^^^^^^^^^^^^^^
  File "/home/airflow/.local/lib/python3.12/site-packages/airflow/utils/operator_helpers.py", line 252, in run
    return self.func(*args, **kwargs)
           ^^^^^^^^^^^^^^^^^^^^^^^^^^
  File "/opt/airflow/dags/ha_etl_process.py", line 132, in extract_data
    history = ha.get_entity_history(entity_consumo_mes)
              ^^^^^^^^^^^^^^^^^^^^^^^^^^^^^^^^^^^^^^^^^
  File "/opt/airflow/dags/ha_etl_process.py", line 46, in get_entity_history
    end_time = datetime.datetime.now(datetime.timezone.utc)
               ^^^^^^^^^^^^^^^^^
AttributeError: type object 'datetime.datetime' has no attribute 'datetime'
[2025-02-28T17:54:21.052+0000] {local_task_job_runner.py:266} INFO - Task exited with return code 1
[2025-02-28T17:54:21.090+0000] {taskinstance.py:3901} INFO - 0 downstream tasks scheduled from follow-on schedule check
[2025-02-28T17:54:21.096+0000] {local_task_job_runner.py:245} INFO - ::endgroup::
