[2025-02-28T02:27:10.771+0000] {local_task_job_runner.py:123} INFO - ::group::Pre task execution logs
[2025-02-28T02:27:10.790+0000] {taskinstance.py:2614} INFO - Dependencies all met for dep_context=non-requeueable deps ti=<TaskInstance: etl_postgres_to_parquet.extract_task manual__2025-02-28T02:27:08.582879+00:00 [queued]>
[2025-02-28T02:27:10.798+0000] {taskinstance.py:2614} INFO - Dependencies all met for dep_context=requeueable deps ti=<TaskInstance: etl_postgres_to_parquet.extract_task manual__2025-02-28T02:27:08.582879+00:00 [queued]>
[2025-02-28T02:27:10.799+0000] {taskinstance.py:2867} INFO - Starting attempt 1 of 2
[2025-02-28T02:27:10.815+0000] {taskinstance.py:2890} INFO - Executing <Task(PythonOperator): extract_task> on 2025-02-28 02:27:08.582879+00:00
[2025-02-28T02:27:10.826+0000] {standard_task_runner.py:104} INFO - Running: ['***', 'tasks', 'run', 'etl_postgres_to_parquet', 'extract_task', 'manual__2025-02-28T02:27:08.582879+00:00', '--job-id', '63', '--raw', '--subdir', 'DAGS_FOLDER/etl_process_to_parquet.py', '--cfg-path', '/tmp/tmpalue51ff']
[2025-02-28T02:27:10.828+0000] {standard_task_runner.py:105} INFO - Job 63: Subtask extract_task
[2025-02-28T02:27:10.830+0000] {logging_mixin.py:190} WARNING - /home/***/.local/lib/python3.12/site-packages/***/task/task_runner/standard_task_runner.py:70 DeprecationWarning: This process (pid=5124) is multi-threaded, use of fork() may lead to deadlocks in the child.
[2025-02-28T02:27:10.831+0000] {standard_task_runner.py:72} INFO - Started process 5191 to run task
[2025-02-28T02:27:10.888+0000] {task_command.py:467} INFO - Running <TaskInstance: etl_postgres_to_parquet.extract_task manual__2025-02-28T02:27:08.582879+00:00 [running]> on host 151d4861bf1b
[2025-02-28T02:27:10.983+0000] {taskinstance.py:3134} INFO - Exporting env vars: AIRFLOW_CTX_DAG_OWNER='***' AIRFLOW_CTX_DAG_ID='etl_postgres_to_parquet' AIRFLOW_CTX_TASK_ID='extract_task' AIRFLOW_CTX_EXECUTION_DATE='2025-02-28T02:27:08.582879+00:00' AIRFLOW_CTX_TRY_NUMBER='1' AIRFLOW_CTX_DAG_RUN_ID='manual__2025-02-28T02:27:08.582879+00:00'
[2025-02-28T02:27:10.985+0000] {logging_mixin.py:190} INFO - Task instance is in running state
[2025-02-28T02:27:10.985+0000] {logging_mixin.py:190} INFO -  Previous state of the Task instance: queued
[2025-02-28T02:27:10.986+0000] {logging_mixin.py:190} INFO - Current task name:extract_task state:running start_date:2025-02-28 02:27:10.791534+00:00
[2025-02-28T02:27:10.986+0000] {logging_mixin.py:190} INFO - Dag name:etl_postgres_to_parquet and current dag run status:running
[2025-02-28T02:27:10.986+0000] {taskinstance.py:732} INFO - ::endgroup::
[2025-02-28T02:27:10.996+0000] {base.py:84} INFO - Retrieving connection '***_default'
[2025-02-28T02:27:11.056+0000] {taskinstance.py:3313} ERROR - Task failed with exception
Traceback (most recent call last):
  File "/home/airflow/.local/lib/python3.12/site-packages/airflow/models/taskinstance.py", line 768, in _execute_task
    result = _execute_callable(context=context, **execute_callable_kwargs)
             ^^^^^^^^^^^^^^^^^^^^^^^^^^^^^^^^^^^^^^^^^^^^^^^^^^^^^^^^^^^^^
  File "/home/airflow/.local/lib/python3.12/site-packages/airflow/models/taskinstance.py", line 734, in _execute_callable
    return ExecutionCallableRunner(
           ^^^^^^^^^^^^^^^^^^^^^^^^
  File "/home/airflow/.local/lib/python3.12/site-packages/airflow/utils/operator_helpers.py", line 252, in run
    return self.func(*args, **kwargs)
           ^^^^^^^^^^^^^^^^^^^^^^^^^^
  File "/home/airflow/.local/lib/python3.12/site-packages/airflow/models/baseoperator.py", line 424, in wrapper
    return func(self, *args, **kwargs)
           ^^^^^^^^^^^^^^^^^^^^^^^^^^^
  File "/home/airflow/.local/lib/python3.12/site-packages/airflow/operators/python.py", line 238, in execute
    return_value = self.execute_callable()
                   ^^^^^^^^^^^^^^^^^^^^^^^
  File "/home/airflow/.local/lib/python3.12/site-packages/airflow/operators/python.py", line 256, in execute_callable
    return runner.run(*self.op_args, **self.op_kwargs)
           ^^^^^^^^^^^^^^^^^^^^^^^^^^^^^^^^^^^^^^^^^^^
  File "/home/airflow/.local/lib/python3.12/site-packages/airflow/utils/operator_helpers.py", line 252, in run
    return self.func(*args, **kwargs)
           ^^^^^^^^^^^^^^^^^^^^^^^^^^
  File "/opt/airflow/dags/etl_process_to_parquet.py", line 14, in extract_data
    conn = postgres_hook.get_conn()
           ^^^^^^^^^^^^^^^^^^^^^^^^
  File "/home/airflow/.local/lib/python3.12/site-packages/airflow/providers/postgres/hooks/postgres.py", line 165, in get_conn
    self.conn = psycopg2.connect(**conn_args)
                ^^^^^^^^^^^^^^^^^^^^^^^^^^^^^
  File "/home/airflow/.local/lib/python3.12/site-packages/psycopg2/__init__.py", line 122, in connect
    conn = _connect(dsn, connection_factory=connection_factory, **kwasync)
           ^^^^^^^^^^^^^^^^^^^^^^^^^^^^^^^^^^^^^^^^^^^^^^^^^^^^^^^^^^^^^^^
UnicodeDecodeError: 'utf-8' codec can't decode byte 0xe1 in position 136: invalid continuation byte
[2025-02-28T02:27:11.074+0000] {logging_mixin.py:190} INFO - Task instance in failure state
[2025-02-28T02:27:11.074+0000] {logging_mixin.py:190} INFO - Task start:2025-02-28 02:27:10.791534+00:00 end:2025-02-28 02:27:11.073453+00:00 duration:0.281919
[2025-02-28T02:27:11.075+0000] {logging_mixin.py:190} INFO - Task:<Task(PythonOperator): extract_task> dag:<DAG: etl_***_to_parquet> dagrun:<DagRun etl_***_to_parquet @ 2025-02-28 02:27:08.582879+00:00: manual__2025-02-28T02:27:08.582879+00:00, state:running, queued_at: 2025-02-28 02:27:08.605419+00:00. externally triggered: True>
[2025-02-28T02:27:11.075+0000] {logging_mixin.py:190} INFO - Failure caused by 'utf-8' codec can't decode byte 0xe1 in position 136: invalid continuation byte
[2025-02-28T02:27:11.076+0000] {taskinstance.py:1226} INFO - Marking task as UP_FOR_RETRY. dag_id=etl_***_to_parquet, task_id=extract_task, run_id=manual__2025-02-28T02:27:08.582879+00:00, execution_date=20250228T022708, start_date=20250228T022710, end_date=20250228T022711
[2025-02-28T02:27:11.109+0000] {taskinstance.py:341} INFO - ::group::Post task execution logs
[2025-02-28T02:27:11.110+0000] {standard_task_runner.py:124} ERROR - Failed to execute job 63 for task extract_task ('utf-8' codec can't decode byte 0xe1 in position 136: invalid continuation byte; 5191)
Traceback (most recent call last):
  File "/home/airflow/.local/lib/python3.12/site-packages/airflow/task/task_runner/standard_task_runner.py", line 117, in _start_by_fork
    ret = args.func(args, dag=self.dag)
          ^^^^^^^^^^^^^^^^^^^^^^^^^^^^^
  File "/home/airflow/.local/lib/python3.12/site-packages/airflow/cli/cli_config.py", line 49, in command
    return func(*args, **kwargs)
           ^^^^^^^^^^^^^^^^^^^^^
  File "/home/airflow/.local/lib/python3.12/site-packages/airflow/utils/cli.py", line 116, in wrapper
    return f(*args, **kwargs)
           ^^^^^^^^^^^^^^^^^^
  File "/home/airflow/.local/lib/python3.12/site-packages/airflow/cli/commands/task_command.py", line 483, in task_run
    task_return_code = _run_task_by_selected_method(args, _dag, ti)
                       ^^^^^^^^^^^^^^^^^^^^^^^^^^^^^^^^^^^^^^^^^^^^
  File "/home/airflow/.local/lib/python3.12/site-packages/airflow/cli/commands/task_command.py", line 256, in _run_task_by_selected_method
    return _run_raw_task(args, ti)
           ^^^^^^^^^^^^^^^^^^^^^^^
  File "/home/airflow/.local/lib/python3.12/site-packages/airflow/cli/commands/task_command.py", line 341, in _run_raw_task
    return ti._run_raw_task(
           ^^^^^^^^^^^^^^^^^
  File "/home/airflow/.local/lib/python3.12/site-packages/airflow/utils/session.py", line 97, in wrapper
    return func(*args, session=session, **kwargs)
           ^^^^^^^^^^^^^^^^^^^^^^^^^^^^^^^^^^^^^^
  File "/home/airflow/.local/lib/python3.12/site-packages/airflow/models/taskinstance.py", line 3006, in _run_raw_task
    return _run_raw_task(
           ^^^^^^^^^^^^^^
  File "/home/airflow/.local/lib/python3.12/site-packages/airflow/models/taskinstance.py", line 274, in _run_raw_task
    TaskInstance._execute_task_with_callbacks(
  File "/home/airflow/.local/lib/python3.12/site-packages/airflow/models/taskinstance.py", line 3161, in _execute_task_with_callbacks
    result = self._execute_task(context, task_orig)
             ^^^^^^^^^^^^^^^^^^^^^^^^^^^^^^^^^^^^^^
  File "/home/airflow/.local/lib/python3.12/site-packages/airflow/models/taskinstance.py", line 3185, in _execute_task
    return _execute_task(self, context, task_orig)
           ^^^^^^^^^^^^^^^^^^^^^^^^^^^^^^^^^^^^^^^
  File "/home/airflow/.local/lib/python3.12/site-packages/airflow/models/taskinstance.py", line 768, in _execute_task
    result = _execute_callable(context=context, **execute_callable_kwargs)
             ^^^^^^^^^^^^^^^^^^^^^^^^^^^^^^^^^^^^^^^^^^^^^^^^^^^^^^^^^^^^^
  File "/home/airflow/.local/lib/python3.12/site-packages/airflow/models/taskinstance.py", line 734, in _execute_callable
    return ExecutionCallableRunner(
           ^^^^^^^^^^^^^^^^^^^^^^^^
  File "/home/airflow/.local/lib/python3.12/site-packages/airflow/utils/operator_helpers.py", line 252, in run
    return self.func(*args, **kwargs)
           ^^^^^^^^^^^^^^^^^^^^^^^^^^
  File "/home/airflow/.local/lib/python3.12/site-packages/airflow/models/baseoperator.py", line 424, in wrapper
    return func(self, *args, **kwargs)
           ^^^^^^^^^^^^^^^^^^^^^^^^^^^
  File "/home/airflow/.local/lib/python3.12/site-packages/airflow/operators/python.py", line 238, in execute
    return_value = self.execute_callable()
                   ^^^^^^^^^^^^^^^^^^^^^^^
  File "/home/airflow/.local/lib/python3.12/site-packages/airflow/operators/python.py", line 256, in execute_callable
    return runner.run(*self.op_args, **self.op_kwargs)
           ^^^^^^^^^^^^^^^^^^^^^^^^^^^^^^^^^^^^^^^^^^^
  File "/home/airflow/.local/lib/python3.12/site-packages/airflow/utils/operator_helpers.py", line 252, in run
    return self.func(*args, **kwargs)
           ^^^^^^^^^^^^^^^^^^^^^^^^^^
  File "/opt/airflow/dags/etl_process_to_parquet.py", line 14, in extract_data
    conn = postgres_hook.get_conn()
           ^^^^^^^^^^^^^^^^^^^^^^^^
  File "/home/airflow/.local/lib/python3.12/site-packages/airflow/providers/postgres/hooks/postgres.py", line 165, in get_conn
    self.conn = psycopg2.connect(**conn_args)
                ^^^^^^^^^^^^^^^^^^^^^^^^^^^^^
  File "/home/airflow/.local/lib/python3.12/site-packages/psycopg2/__init__.py", line 122, in connect
    conn = _connect(dsn, connection_factory=connection_factory, **kwasync)
           ^^^^^^^^^^^^^^^^^^^^^^^^^^^^^^^^^^^^^^^^^^^^^^^^^^^^^^^^^^^^^^^
UnicodeDecodeError: 'utf-8' codec can't decode byte 0xe1 in position 136: invalid continuation byte
[2025-02-28T02:27:11.127+0000] {local_task_job_runner.py:266} INFO - Task exited with return code 1
[2025-02-28T02:27:11.151+0000] {taskinstance.py:3901} INFO - 0 downstream tasks scheduled from follow-on schedule check
[2025-02-28T02:27:11.154+0000] {local_task_job_runner.py:245} INFO - ::endgroup::
