[2025-02-28T21:50:54.283+0000] {local_task_job_runner.py:123} INFO - ::group::Pre task execution logs
[2025-02-28T21:50:54.304+0000] {taskinstance.py:2614} INFO - Dependencies all met for dep_context=non-requeueable deps ti=<TaskInstance: ha_etl_process.extract_task manual__2025-02-28T21:40:09.515454+00:00 [queued]>
[2025-02-28T21:50:54.313+0000] {taskinstance.py:2614} INFO - Dependencies all met for dep_context=requeueable deps ti=<TaskInstance: ha_etl_process.extract_task manual__2025-02-28T21:40:09.515454+00:00 [queued]>
[2025-02-28T21:50:54.314+0000] {taskinstance.py:2867} INFO - Starting attempt 2 of 2
[2025-02-28T21:50:54.335+0000] {taskinstance.py:2890} INFO - Executing <Task(PythonOperator): extract_task> on 2025-02-28 21:40:09.515454+00:00
[2025-02-28T21:50:54.351+0000] {logging_mixin.py:190} WARNING - /home/***/.local/lib/python3.12/site-packages/***/task/task_runner/standard_task_runner.py:70 DeprecationWarning: This process (pid=7158) is multi-threaded, use of fork() may lead to deadlocks in the child.
[2025-02-28T21:50:54.352+0000] {standard_task_runner.py:72} INFO - Started process 7159 to run task
[2025-02-28T21:50:54.351+0000] {standard_task_runner.py:104} INFO - Running: ['***', 'tasks', 'run', 'ha_etl_process', 'extract_task', 'manual__2025-02-28T21:40:09.515454+00:00', '--job-id', '133', '--raw', '--subdir', 'DAGS_FOLDER/ha_etl_process.py', '--cfg-path', '/tmp/tmp583kxlqf']
[2025-02-28T21:50:54.354+0000] {standard_task_runner.py:105} INFO - Job 133: Subtask extract_task
[2025-02-28T21:50:54.420+0000] {task_command.py:467} INFO - Running <TaskInstance: ha_etl_process.extract_task manual__2025-02-28T21:40:09.515454+00:00 [running]> on host 151d4861bf1b
[2025-02-28T21:50:54.516+0000] {taskinstance.py:3134} INFO - Exporting env vars: AIRFLOW_CTX_DAG_OWNER='***' AIRFLOW_CTX_DAG_ID='ha_etl_process' AIRFLOW_CTX_TASK_ID='extract_task' AIRFLOW_CTX_EXECUTION_DATE='2025-02-28T21:40:09.515454+00:00' AIRFLOW_CTX_TRY_NUMBER='2' AIRFLOW_CTX_DAG_RUN_ID='manual__2025-02-28T21:40:09.515454+00:00'
[2025-02-28T21:50:54.518+0000] {logging_mixin.py:190} INFO - Task instance is in running state
[2025-02-28T21:50:54.518+0000] {logging_mixin.py:190} INFO -  Previous state of the Task instance: queued
[2025-02-28T21:50:54.519+0000] {logging_mixin.py:190} INFO - Current task name:extract_task state:running start_date:2025-02-28 21:50:54.305054+00:00
[2025-02-28T21:50:54.519+0000] {logging_mixin.py:190} INFO - Dag name:ha_etl_process and current dag run status:running
[2025-02-28T21:50:54.520+0000] {taskinstance.py:732} INFO - ::endgroup::
[2025-02-28T21:50:54.521+0000] {logging_mixin.py:190} INFO - üîç Tentando se conectar ao Home Assistant...
[2025-02-28T21:50:54.521+0000] {logging_mixin.py:190} INFO - üì¶ Extraindo hist√≥rico da entidade sensor.abc_consumo_ativo_total...
[2025-02-28T21:51:04.538+0000] {logging_mixin.py:190} INFO - ‚ùå Erro de conex√£o: HTTPConnectionPool(host='192.168.1.110', port=8123): Max retries exceeded with url: /api/history/period/2025-01-29T21:50:54.522465+00:00?end_time=2025-02-28T21%3A50%3A54.522465%2B00%3A00&filter_entity_id=sensor.abc_consumo_ativo_total (Caused by ConnectTimeoutError(<urllib3.connection.HTTPConnection object at 0x7fbddec02420>, 'Connection to 192.168.1.110 timed out. (connect timeout=10)'))
[2025-02-28T21:51:14.542+0000] {logging_mixin.py:190} INFO - ‚ùå Erro de conex√£o: HTTPConnectionPool(host='192.168.1.110', port=8123): Max retries exceeded with url: /api/history/period/2024-12-30T21:50:54.522464+00:00?end_time=2025-01-29T21%3A50%3A54.522464%2B00%3A00&filter_entity_id=sensor.abc_consumo_ativo_total (Caused by ConnectTimeoutError(<urllib3.connection.HTTPConnection object at 0x7fbddeca5370>, 'Connection to 192.168.1.110 timed out. (connect timeout=10)'))
[2025-02-28T21:51:24.553+0000] {logging_mixin.py:190} INFO - ‚ùå Erro de conex√£o: HTTPConnectionPool(host='192.168.1.110', port=8123): Max retries exceeded with url: /api/history/period/2024-11-30T21:50:54.522463+00:00?end_time=2024-12-30T21%3A50%3A54.522463%2B00%3A00&filter_entity_id=sensor.abc_consumo_ativo_total (Caused by ConnectTimeoutError(<urllib3.connection.HTTPConnection object at 0x7fbddeca5b20>, 'Connection to 192.168.1.110 timed out. (connect timeout=10)'))
[2025-02-28T21:51:34.563+0000] {logging_mixin.py:190} INFO - ‚ùå Erro de conex√£o: HTTPConnectionPool(host='192.168.1.110', port=8123): Max retries exceeded with url: /api/history/period/2024-10-31T21:50:54.522462+00:00?end_time=2024-11-30T21%3A50%3A54.522462%2B00%3A00&filter_entity_id=sensor.abc_consumo_ativo_total (Caused by ConnectTimeoutError(<urllib3.connection.HTTPConnection object at 0x7fbddeca6690>, 'Connection to 192.168.1.110 timed out. (connect timeout=10)'))
[2025-02-28T21:51:44.570+0000] {logging_mixin.py:190} INFO - ‚ùå Erro de conex√£o: HTTPConnectionPool(host='192.168.1.110', port=8123): Max retries exceeded with url: /api/history/period/2024-10-01T21:50:54.522461+00:00?end_time=2024-10-31T21%3A50%3A54.522461%2B00%3A00&filter_entity_id=sensor.abc_consumo_ativo_total (Caused by ConnectTimeoutError(<urllib3.connection.HTTPConnection object at 0x7fbddeca6ff0>, 'Connection to 192.168.1.110 timed out. (connect timeout=10)'))
[2025-02-28T21:51:54.585+0000] {logging_mixin.py:190} INFO - ‚ùå Erro de conex√£o: HTTPConnectionPool(host='192.168.1.110', port=8123): Max retries exceeded with url: /api/history/period/2024-09-01T21:50:54.522460+00:00?end_time=2024-10-01T21%3A50%3A54.522460%2B00%3A00&filter_entity_id=sensor.abc_consumo_ativo_total (Caused by ConnectTimeoutError(<urllib3.connection.HTTPConnection object at 0x7fbddeca7500>, 'Connection to 192.168.1.110 timed out. (connect timeout=10)'))
[2025-02-28T21:52:04.601+0000] {logging_mixin.py:190} INFO - ‚ùå Erro de conex√£o: HTTPConnectionPool(host='192.168.1.110', port=8123): Max retries exceeded with url: /api/history/period/2024-08-02T21:50:54.522459+00:00?end_time=2024-09-01T21%3A50%3A54.522459%2B00%3A00&filter_entity_id=sensor.abc_consumo_ativo_total (Caused by ConnectTimeoutError(<urllib3.connection.HTTPConnection object at 0x7fbddeca7500>, 'Connection to 192.168.1.110 timed out. (connect timeout=10)'))
[2025-02-28T21:52:14.614+0000] {logging_mixin.py:190} INFO - ‚ùå Erro de conex√£o: HTTPConnectionPool(host='192.168.1.110', port=8123): Max retries exceeded with url: /api/history/period/2024-07-03T21:50:54.522458+00:00?end_time=2024-08-02T21%3A50%3A54.522458%2B00%3A00&filter_entity_id=sensor.abc_consumo_ativo_total (Caused by ConnectTimeoutError(<urllib3.connection.HTTPConnection object at 0x7fbddeca6a20>, 'Connection to 192.168.1.110 timed out. (connect timeout=10)'))
[2025-02-28T21:52:24.627+0000] {logging_mixin.py:190} INFO - ‚ùå Erro de conex√£o: HTTPConnectionPool(host='192.168.1.110', port=8123): Max retries exceeded with url: /api/history/period/2024-06-03T21:50:54.522457+00:00?end_time=2024-07-03T21%3A50%3A54.522457%2B00%3A00&filter_entity_id=sensor.abc_consumo_ativo_total (Caused by ConnectTimeoutError(<urllib3.connection.HTTPConnection object at 0x7fbddeca5dc0>, 'Connection to 192.168.1.110 timed out. (connect timeout=10)'))
[2025-02-28T21:52:34.642+0000] {logging_mixin.py:190} INFO - ‚ùå Erro de conex√£o: HTTPConnectionPool(host='192.168.1.110', port=8123): Max retries exceeded with url: /api/history/period/2024-05-04T21:50:54.522456+00:00?end_time=2024-06-03T21%3A50%3A54.522456%2B00%3A00&filter_entity_id=sensor.abc_consumo_ativo_total (Caused by ConnectTimeoutError(<urllib3.connection.HTTPConnection object at 0x7fbddeca5220>, 'Connection to 192.168.1.110 timed out. (connect timeout=10)'))
[2025-02-28T21:52:44.653+0000] {logging_mixin.py:190} INFO - ‚ùå Erro de conex√£o: HTTPConnectionPool(host='192.168.1.110', port=8123): Max retries exceeded with url: /api/history/period/2024-04-04T21:50:54.522455+00:00?end_time=2024-05-04T21%3A50%3A54.522455%2B00%3A00&filter_entity_id=sensor.abc_consumo_ativo_total (Caused by ConnectTimeoutError(<urllib3.connection.HTTPConnection object at 0x7fbddecdc6b0>, 'Connection to 192.168.1.110 timed out. (connect timeout=10)'))
[2025-02-28T21:52:54.667+0000] {logging_mixin.py:190} INFO - ‚ùå Erro de conex√£o: HTTPConnectionPool(host='192.168.1.110', port=8123): Max retries exceeded with url: /api/history/period/2024-03-05T21:50:54.522454+00:00?end_time=2024-04-04T21%3A50%3A54.522454%2B00%3A00&filter_entity_id=sensor.abc_consumo_ativo_total (Caused by ConnectTimeoutError(<urllib3.connection.HTTPConnection object at 0x7fbddecdcfe0>, 'Connection to 192.168.1.110 timed out. (connect timeout=10)'))
[2025-02-28T21:53:04.684+0000] {logging_mixin.py:190} INFO - ‚ùå Erro de conex√£o: HTTPConnectionPool(host='192.168.1.110', port=8123): Max retries exceeded with url: /api/history/period/2024-02-04T21:50:54.522453+00:00?end_time=2024-03-05T21%3A50%3A54.522453%2B00%3A00&filter_entity_id=sensor.abc_consumo_ativo_total (Caused by ConnectTimeoutError(<urllib3.connection.HTTPConnection object at 0x7fbddec6ffe0>, 'Connection to 192.168.1.110 timed out. (connect timeout=10)'))
[2025-02-28T21:53:14.697+0000] {logging_mixin.py:190} INFO - ‚ùå Erro de conex√£o: HTTPConnectionPool(host='192.168.1.110', port=8123): Max retries exceeded with url: /api/history/period/2024-01-05T21:50:54.522452+00:00?end_time=2024-02-04T21%3A50%3A54.522452%2B00%3A00&filter_entity_id=sensor.abc_consumo_ativo_total (Caused by ConnectTimeoutError(<urllib3.connection.HTTPConnection object at 0x7fbddeca6600>, 'Connection to 192.168.1.110 timed out. (connect timeout=10)'))
[2025-02-28T21:53:24.710+0000] {logging_mixin.py:190} INFO - ‚ùå Erro de conex√£o: HTTPConnectionPool(host='192.168.1.110', port=8123): Max retries exceeded with url: /api/history/period/2023-12-06T21:50:54.522451+00:00?end_time=2024-01-05T21%3A50%3A54.522451%2B00%3A00&filter_entity_id=sensor.abc_consumo_ativo_total (Caused by ConnectTimeoutError(<urllib3.connection.HTTPConnection object at 0x7fbddeca6e10>, 'Connection to 192.168.1.110 timed out. (connect timeout=10)'))
[2025-02-28T21:53:30.414+0000] {local_task_job_runner.py:127} ERROR - Received SIGTERM. Terminating subprocesses
[2025-02-28T21:53:30.430+0000] {process_utils.py:132} INFO - Sending 15 to group 7159. PIDs of all processes in the group: [7159]
[2025-02-28T21:53:30.431+0000] {process_utils.py:87} INFO - Sending the signal 15 to group 7159
[2025-02-28T21:53:30.432+0000] {taskinstance.py:3094} ERROR - Received SIGTERM. Terminating subprocesses.
[2025-02-28T21:53:30.472+0000] {taskinstance.py:3095} ERROR - Stacktrace: 
  File "/home/***/.local/bin/***", line 8, in <module>
    sys.exit(main())
  File "/home/***/.local/lib/python3.12/site-packages/***/__main__.py", line 62, in main
    args.func(args)
  File "/home/***/.local/lib/python3.12/site-packages/***/cli/cli_config.py", line 49, in command
    return func(*args, **kwargs)
  File "/home/***/.local/lib/python3.12/site-packages/***/utils/cli.py", line 116, in wrapper
    return f(*args, **kwargs)
  File "/home/***/.local/lib/python3.12/site-packages/***/utils/providers_configuration_loader.py", line 55, in wrapped_function
    return func(*args, **kwargs)
  File "/home/***/.local/lib/python3.12/site-packages/***/cli/commands/scheduler_command.py", line 56, in scheduler
    run_command_with_daemon_option(
  File "/home/***/.local/lib/python3.12/site-packages/***/cli/commands/daemon_utils.py", line 86, in run_command_with_daemon_option
    callback()
  File "/home/***/.local/lib/python3.12/site-packages/***/cli/commands/scheduler_command.py", line 59, in <lambda>
    callback=lambda: _run_scheduler_job(args),
  File "/home/***/.local/lib/python3.12/site-packages/***/cli/commands/scheduler_command.py", line 47, in _run_scheduler_job
    run_job(job=job_runner.job, execute_callable=job_runner._execute)
  File "/home/***/.local/lib/python3.12/site-packages/***/utils/session.py", line 97, in wrapper
    return func(*args, session=session, **kwargs)
  File "/home/***/.local/lib/python3.12/site-packages/***/jobs/job.py", line 421, in run_job
    return execute_job(job, execute_callable=execute_callable)
  File "/home/***/.local/lib/python3.12/site-packages/***/jobs/job.py", line 450, in execute_job
    ret = execute_callable()
  File "/home/***/.local/lib/python3.12/site-packages/***/jobs/scheduler_job_runner.py", line 990, in _execute
    executor.start()
  File "/home/***/.local/lib/python3.12/site-packages/***/executors/local_executor.py", line 392, in start
    self.impl.start()
  File "/home/***/.local/lib/python3.12/site-packages/***/executors/local_executor.py", line 330, in start
    worker.start()
  File "/usr/local/lib/python3.12/multiprocessing/process.py", line 121, in start
    self._popen = self._Popen(self)
  File "/usr/local/lib/python3.12/multiprocessing/context.py", line 224, in _Popen
    return _default_context.get_context().Process._Popen(process_obj)
  File "/usr/local/lib/python3.12/multiprocessing/context.py", line 282, in _Popen
    return Popen(process_obj)
  File "/usr/local/lib/python3.12/multiprocessing/popen_fork.py", line 19, in __init__
    self._launch(process_obj)
  File "/usr/local/lib/python3.12/multiprocessing/popen_fork.py", line 71, in _launch
    code = process_obj._bootstrap(parent_sentinel=child_r)
  File "/usr/local/lib/python3.12/multiprocessing/process.py", line 314, in _bootstrap
    self.run()
  File "/home/***/.local/lib/python3.12/site-packages/***/executors/local_executor.py", line 80, in run
    return super().run()
  File "/usr/local/lib/python3.12/multiprocessing/process.py", line 108, in run
    self._target(*self._args, **self._kwargs)
  File "/home/***/.local/lib/python3.12/site-packages/***/traces/tracer.py", line 58, in wrapper
    return func(*args, **kwargs)
  File "/home/***/.local/lib/python3.12/site-packages/***/executors/local_executor.py", line 211, in do_work
    self.execute_work(key=key, command=command)
  File "/home/***/.local/lib/python3.12/site-packages/***/traces/tracer.py", line 58, in wrapper
    return func(*args, **kwargs)
  File "/home/***/.local/lib/python3.12/site-packages/***/executors/local_executor.py", line 100, in execute_work
    state = self._execute_work_in_fork(command)
  File "/home/***/.local/lib/python3.12/site-packages/***/traces/tracer.py", line 58, in wrapper
    return func(*args, **kwargs)
  File "/home/***/.local/lib/python3.12/site-packages/***/executors/local_executor.py", line 142, in _execute_work_in_fork
    args.func(args)
  File "/home/***/.local/lib/python3.12/site-packages/***/cli/cli_config.py", line 49, in command
    return func(*args, **kwargs)
  File "/home/***/.local/lib/python3.12/site-packages/***/utils/cli.py", line 116, in wrapper
    return f(*args, **kwargs)
  File "/home/***/.local/lib/python3.12/site-packages/***/cli/commands/task_command.py", line 483, in task_run
    task_return_code = _run_task_by_selected_method(args, _dag, ti)
  File "/home/***/.local/lib/python3.12/site-packages/***/cli/commands/task_command.py", line 254, in _run_task_by_selected_method
    return _run_task_by_local_task_job(args, ti)
  File "/home/***/.local/lib/python3.12/site-packages/***/cli/commands/task_command.py", line 322, in _run_task_by_local_task_job
    ret = run_job(job=job_runner.job, execute_callable=job_runner._execute)
  File "/home/***/.local/lib/python3.12/site-packages/***/utils/session.py", line 97, in wrapper
    return func(*args, session=session, **kwargs)
  File "/home/***/.local/lib/python3.12/site-packages/***/jobs/job.py", line 421, in run_job
    return execute_job(job, execute_callable=execute_callable)
  File "/home/***/.local/lib/python3.12/site-packages/***/jobs/job.py", line 450, in execute_job
    ret = execute_callable()
  File "/home/***/.local/lib/python3.12/site-packages/***/jobs/local_task_job_runner.py", line 171, in _execute
    self.task_runner.start()
  File "/home/***/.local/lib/python3.12/site-packages/***/task/task_runner/standard_task_runner.py", line 55, in start
    self.process = self._start_by_fork()
  File "/home/***/.local/lib/python3.12/site-packages/***/task/task_runner/standard_task_runner.py", line 117, in _start_by_fork
    ret = args.func(args, dag=self.dag)
  File "/home/***/.local/lib/python3.12/site-packages/***/cli/cli_config.py", line 49, in command
    return func(*args, **kwargs)
  File "/home/***/.local/lib/python3.12/site-packages/***/utils/cli.py", line 116, in wrapper
    return f(*args, **kwargs)
  File "/home/***/.local/lib/python3.12/site-packages/***/cli/commands/task_command.py", line 483, in task_run
    task_return_code = _run_task_by_selected_method(args, _dag, ti)
  File "/home/***/.local/lib/python3.12/site-packages/***/cli/commands/task_command.py", line 256, in _run_task_by_selected_method
    return _run_raw_task(args, ti)
  File "/home/***/.local/lib/python3.12/site-packages/***/cli/commands/task_command.py", line 341, in _run_raw_task
    return ti._run_raw_task(
  File "/home/***/.local/lib/python3.12/site-packages/***/utils/session.py", line 97, in wrapper
    return func(*args, session=session, **kwargs)
  File "/home/***/.local/lib/python3.12/site-packages/***/models/taskinstance.py", line 3006, in _run_raw_task
    return _run_raw_task(
  File "/home/***/.local/lib/python3.12/site-packages/***/models/taskinstance.py", line 274, in _run_raw_task
    TaskInstance._execute_task_with_callbacks(
  File "/home/***/.local/lib/python3.12/site-packages/***/models/taskinstance.py", line 3161, in _execute_task_with_callbacks
    result = self._execute_task(context, task_orig)
  File "/home/***/.local/lib/python3.12/site-packages/***/models/taskinstance.py", line 3185, in _execute_task
    return _execute_task(self, context, task_orig)
  File "/home/***/.local/lib/python3.12/site-packages/***/models/taskinstance.py", line 768, in _execute_task
    result = _execute_callable(context=context, **execute_callable_kwargs)
  File "/home/***/.local/lib/python3.12/site-packages/***/models/taskinstance.py", line 734, in _execute_callable
    return ExecutionCallableRunner(
  File "/home/***/.local/lib/python3.12/site-packages/***/utils/operator_helpers.py", line 252, in run
    return self.func(*args, **kwargs)
  File "/home/***/.local/lib/python3.12/site-packages/***/models/baseoperator.py", line 424, in wrapper
    return func(self, *args, **kwargs)
  File "/home/***/.local/lib/python3.12/site-packages/***/operators/python.py", line 238, in execute
    return_value = self.execute_callable()
  File "/home/***/.local/lib/python3.12/site-packages/***/operators/python.py", line 256, in execute_callable
    return runner.run(*self.op_args, **self.op_kwargs)
  File "/home/***/.local/lib/python3.12/site-packages/***/utils/operator_helpers.py", line 252, in run
    return self.func(*args, **kwargs)
  File "/opt/***/dags/ha_etl_process.py", line 107, in extract_data
    print(f"Error: {str(e)}")
  File "/opt/***/dags/ha_etl_process.py", line 55, in get_entity_history
    df = self._fetch_data(url, params=params)
  File "/opt/***/dags/ha_etl_process.py", line 70, in _fetch_data
    response = requests.get(url, headers=self.headers, params=params, timeout=10)
  File "/home/***/.local/lib/python3.12/site-packages/requests/api.py", line 73, in get
    return request("get", url, params=params, **kwargs)
  File "/home/***/.local/lib/python3.12/site-packages/requests/api.py", line 59, in request
    return session.request(method=method, url=url, **kwargs)
  File "/home/***/.local/lib/python3.12/site-packages/requests/sessions.py", line 589, in request
    resp = self.send(prep, **send_kwargs)
  File "/home/***/.local/lib/python3.12/site-packages/requests/sessions.py", line 703, in send
    r = adapter.send(request, **kwargs)
  File "/home/***/.local/lib/python3.12/site-packages/requests/adapters.py", line 667, in send
    resp = conn.urlopen(
  File "/home/***/.local/lib/python3.12/site-packages/urllib3/connectionpool.py", line 787, in urlopen
    response = self._make_request(
  File "/home/***/.local/lib/python3.12/site-packages/urllib3/connectionpool.py", line 493, in _make_request
    conn.request(
  File "/home/***/.local/lib/python3.12/site-packages/urllib3/connection.py", line 445, in request
    self.endheaders()
  File "/usr/local/lib/python3.12/http/client.py", line 1333, in endheaders
    self._send_output(message_body, encode_chunked=encode_chunked)
  File "/usr/local/lib/python3.12/http/client.py", line 1093, in _send_output
    self.send(msg)
  File "/usr/local/lib/python3.12/http/client.py", line 1037, in send
    self.connect()
  File "/home/***/.local/lib/python3.12/site-packages/urllib3/connection.py", line 276, in connect
    self.sock = self._new_conn()
  File "/home/***/.local/lib/python3.12/site-packages/urllib3/connection.py", line 198, in _new_conn
    sock = connection.create_connection(
  File "/home/***/.local/lib/python3.12/site-packages/urllib3/util/connection.py", line 73, in create_connection
    sock.connect(sa)
  File "/home/***/.local/lib/python3.12/site-packages/***/models/taskinstance.py", line 3095, in signal_handler
    self.log.error("Stacktrace: \n%s", "".join(traceback.format_stack()))

[2025-02-28T21:53:30.490+0000] {taskinstance.py:3313} ERROR - Task failed with exception
Traceback (most recent call last):
  File "/home/airflow/.local/lib/python3.12/site-packages/airflow/models/taskinstance.py", line 768, in _execute_task
    result = _execute_callable(context=context, **execute_callable_kwargs)
             ^^^^^^^^^^^^^^^^^^^^^^^^^^^^^^^^^^^^^^^^^^^^^^^^^^^^^^^^^^^^^
  File "/home/airflow/.local/lib/python3.12/site-packages/airflow/models/taskinstance.py", line 734, in _execute_callable
    return ExecutionCallableRunner(
           ^^^^^^^^^^^^^^^^^^^^^^^^
  File "/home/airflow/.local/lib/python3.12/site-packages/airflow/utils/operator_helpers.py", line 252, in run
    return self.func(*args, **kwargs)
           ^^^^^^^^^^^^^^^^^^^^^^^^^^
  File "/home/airflow/.local/lib/python3.12/site-packages/airflow/models/baseoperator.py", line 424, in wrapper
    return func(self, *args, **kwargs)
           ^^^^^^^^^^^^^^^^^^^^^^^^^^^
  File "/home/airflow/.local/lib/python3.12/site-packages/airflow/operators/python.py", line 238, in execute
    return_value = self.execute_callable()
                   ^^^^^^^^^^^^^^^^^^^^^^^
  File "/home/airflow/.local/lib/python3.12/site-packages/airflow/operators/python.py", line 256, in execute_callable
    return runner.run(*self.op_args, **self.op_kwargs)
           ^^^^^^^^^^^^^^^^^^^^^^^^^^^^^^^^^^^^^^^^^^^
  File "/home/airflow/.local/lib/python3.12/site-packages/airflow/utils/operator_helpers.py", line 252, in run
    return self.func(*args, **kwargs)
           ^^^^^^^^^^^^^^^^^^^^^^^^^^
  File "/opt/airflow/dags/ha_etl_process.py", line 107, in extract_data
    print(f"Error: {str(e)}")
          ^^^^^^^^^^^^^^^^^^^^
  File "/opt/airflow/dags/ha_etl_process.py", line 55, in get_entity_history
    df = self._fetch_data(url, params=params)
         ^^^^^^^^^^^^^^^^^^^^^^^^^^^^^^^^^^^^
  File "/opt/airflow/dags/ha_etl_process.py", line 70, in _fetch_data
    response = requests.get(url, headers=self.headers, params=params, timeout=10)
               ^^^^^^^^^^^^^^^^^^^^^^^^^^^^^^^^^^^^^^^^^^^^^^^^^^^^^^^^^^^^^^^^^^
  File "/home/airflow/.local/lib/python3.12/site-packages/requests/api.py", line 73, in get
    return request("get", url, params=params, **kwargs)
           ^^^^^^^^^^^^^^^^^^^^^^^^^^^^^^^^^^^^^^^^^^^^
  File "/home/airflow/.local/lib/python3.12/site-packages/requests/api.py", line 59, in request
    return session.request(method=method, url=url, **kwargs)
           ^^^^^^^^^^^^^^^^^^^^^^^^^^^^^^^^^^^^^^^^^^^^^^^^^
  File "/home/airflow/.local/lib/python3.12/site-packages/requests/sessions.py", line 589, in request
    resp = self.send(prep, **send_kwargs)
           ^^^^^^^^^^^^^^^^^^^^^^^^^^^^^^
  File "/home/airflow/.local/lib/python3.12/site-packages/requests/sessions.py", line 703, in send
    r = adapter.send(request, **kwargs)
        ^^^^^^^^^^^^^^^^^^^^^^^^^^^^^^^
  File "/home/airflow/.local/lib/python3.12/site-packages/requests/adapters.py", line 667, in send
    resp = conn.urlopen(
           ^^^^^^^^^^^^^
  File "/home/airflow/.local/lib/python3.12/site-packages/urllib3/connectionpool.py", line 787, in urlopen
    response = self._make_request(
               ^^^^^^^^^^^^^^^^^^^
  File "/home/airflow/.local/lib/python3.12/site-packages/urllib3/connectionpool.py", line 493, in _make_request
    conn.request(
  File "/home/airflow/.local/lib/python3.12/site-packages/urllib3/connection.py", line 445, in request
    self.endheaders()
  File "/usr/local/lib/python3.12/http/client.py", line 1333, in endheaders
    self._send_output(message_body, encode_chunked=encode_chunked)
  File "/usr/local/lib/python3.12/http/client.py", line 1093, in _send_output
    self.send(msg)
  File "/usr/local/lib/python3.12/http/client.py", line 1037, in send
    self.connect()
  File "/home/airflow/.local/lib/python3.12/site-packages/urllib3/connection.py", line 276, in connect
    self.sock = self._new_conn()
                ^^^^^^^^^^^^^^^^
  File "/home/airflow/.local/lib/python3.12/site-packages/urllib3/connection.py", line 198, in _new_conn
    sock = connection.create_connection(
           ^^^^^^^^^^^^^^^^^^^^^^^^^^^^^
  File "/home/airflow/.local/lib/python3.12/site-packages/urllib3/util/connection.py", line 73, in create_connection
    sock.connect(sa)
  File "/home/airflow/.local/lib/python3.12/site-packages/airflow/models/taskinstance.py", line 3097, in signal_handler
    raise AirflowTaskTerminated("Task received SIGTERM signal")
airflow.exceptions.AirflowTaskTerminated: Task received SIGTERM signal
[2025-02-28T21:53:30.497+0000] {logging_mixin.py:190} INFO - Task instance in failure state
[2025-02-28T21:53:30.498+0000] {logging_mixin.py:190} INFO - Task start:2025-02-28 21:50:54.305054+00:00 end:2025-02-28 21:53:30.496908+00:00 duration:156.191854
[2025-02-28T21:53:30.499+0000] {logging_mixin.py:190} INFO - Task:<Task(PythonOperator): extract_task> dag:<DAG: ha_etl_process> dagrun:<DagRun ha_etl_process @ 2025-02-28 21:40:09.515454+00:00: manual__2025-02-28T21:40:09.515454+00:00, state:running, queued_at: 2025-02-28 21:40:09.545517+00:00. externally triggered: True>
[2025-02-28T21:53:30.499+0000] {logging_mixin.py:190} INFO - Failure caused by Task received SIGTERM signal
[2025-02-28T21:53:30.500+0000] {taskinstance.py:1226} INFO - Marking task as FAILED. dag_id=ha_etl_process, task_id=extract_task, run_id=manual__2025-02-28T21:40:09.515454+00:00, execution_date=20250228T214009, start_date=20250228T215054, end_date=20250228T215330
[2025-02-28T21:53:30.538+0000] {taskinstance.py:341} INFO - ::group::Post task execution logs
[2025-02-28T21:53:30.567+0000] {process_utils.py:80} INFO - Process psutil.Process(pid=7159, status='terminated', exitcode=2, started='21:50:54') (7159) terminated with exit code 2
[2025-02-28T21:53:30.568+0000] {local_task_job_runner.py:266} INFO - Task exited with return code 143
[2025-02-28T21:53:30.606+0000] {taskinstance.py:3901} INFO - 0 downstream tasks scheduled from follow-on schedule check
[2025-02-28T21:53:31.377+0000] {local_task_job_runner.py:245} INFO - ::endgroup::
