[2025-02-28T21:40:11.651+0000] {local_task_job_runner.py:123} INFO - ::group::Pre task execution logs
[2025-02-28T21:40:11.670+0000] {taskinstance.py:2614} INFO - Dependencies all met for dep_context=non-requeueable deps ti=<TaskInstance: ha_etl_process.extract_task manual__2025-02-28T21:40:09.515454+00:00 [queued]>
[2025-02-28T21:40:11.678+0000] {taskinstance.py:2614} INFO - Dependencies all met for dep_context=requeueable deps ti=<TaskInstance: ha_etl_process.extract_task manual__2025-02-28T21:40:09.515454+00:00 [queued]>
[2025-02-28T21:40:11.679+0000] {taskinstance.py:2867} INFO - Starting attempt 1 of 2
[2025-02-28T21:40:11.696+0000] {taskinstance.py:2890} INFO - Executing <Task(PythonOperator): extract_task> on 2025-02-28 21:40:09.515454+00:00
[2025-02-28T21:40:11.705+0000] {standard_task_runner.py:104} INFO - Running: ['***', 'tasks', 'run', 'ha_etl_process', 'extract_task', 'manual__2025-02-28T21:40:09.515454+00:00', '--job-id', '131', '--raw', '--subdir', 'DAGS_FOLDER/ha_etl_process.py', '--cfg-path', '/tmp/tmpd56ohaac']
[2025-02-28T21:40:11.706+0000] {standard_task_runner.py:105} INFO - Job 131: Subtask extract_task
[2025-02-28T21:40:11.711+0000] {logging_mixin.py:190} WARNING - /home/***/.local/lib/python3.12/site-packages/***/task/task_runner/standard_task_runner.py:70 DeprecationWarning: This process (pid=801) is multi-threaded, use of fork() may lead to deadlocks in the child.
[2025-02-28T21:40:11.712+0000] {standard_task_runner.py:72} INFO - Started process 802 to run task
[2025-02-28T21:40:11.760+0000] {task_command.py:467} INFO - Running <TaskInstance: ha_etl_process.extract_task manual__2025-02-28T21:40:09.515454+00:00 [running]> on host 151d4861bf1b
[2025-02-28T21:40:11.844+0000] {taskinstance.py:3134} INFO - Exporting env vars: AIRFLOW_CTX_DAG_OWNER='***' AIRFLOW_CTX_DAG_ID='ha_etl_process' AIRFLOW_CTX_TASK_ID='extract_task' AIRFLOW_CTX_EXECUTION_DATE='2025-02-28T21:40:09.515454+00:00' AIRFLOW_CTX_TRY_NUMBER='1' AIRFLOW_CTX_DAG_RUN_ID='manual__2025-02-28T21:40:09.515454+00:00'
[2025-02-28T21:40:11.845+0000] {logging_mixin.py:190} INFO - Task instance is in running state
[2025-02-28T21:40:11.845+0000] {logging_mixin.py:190} INFO -  Previous state of the Task instance: queued
[2025-02-28T21:40:11.846+0000] {logging_mixin.py:190} INFO - Current task name:extract_task state:running start_date:2025-02-28 21:40:11.671154+00:00
[2025-02-28T21:40:11.847+0000] {logging_mixin.py:190} INFO - Dag name:ha_etl_process and current dag run status:running
[2025-02-28T21:40:11.847+0000] {taskinstance.py:732} INFO - ::endgroup::
[2025-02-28T21:40:11.848+0000] {logging_mixin.py:190} INFO - üîç Tentando se conectar ao Home Assistant...
[2025-02-28T21:40:11.848+0000] {logging_mixin.py:190} INFO - üì¶ Extraindo hist√≥rico da entidade sensor.abc_consumo_ativo_total...
[2025-02-28T21:40:21.864+0000] {logging_mixin.py:190} INFO - ‚ùå Erro de conex√£o: HTTPConnectionPool(host='192.168.1.110', port=8123): Max retries exceeded with url: /api/history/period/2025-01-29T21:40:11.849222+00:00?end_time=2025-02-28T21%3A40%3A11.849222%2B00%3A00&filter_entity_id=sensor.abc_consumo_ativo_total (Caused by ConnectTimeoutError(<urllib3.connection.HTTPConnection object at 0x7fbddec3d310>, 'Connection to 192.168.1.110 timed out. (connect timeout=10)'))
[2025-02-28T21:40:31.872+0000] {logging_mixin.py:190} INFO - ‚ùå Erro de conex√£o: HTTPConnectionPool(host='192.168.1.110', port=8123): Max retries exceeded with url: /api/history/period/2024-12-30T21:40:11.849221+00:00?end_time=2025-01-29T21%3A40%3A11.849221%2B00%3A00&filter_entity_id=sensor.abc_consumo_ativo_total (Caused by ConnectTimeoutError(<urllib3.connection.HTTPConnection object at 0x7fbddeca95b0>, 'Connection to 192.168.1.110 timed out. (connect timeout=10)'))
[2025-02-28T21:40:41.883+0000] {logging_mixin.py:190} INFO - ‚ùå Erro de conex√£o: HTTPConnectionPool(host='192.168.1.110', port=8123): Max retries exceeded with url: /api/history/period/2024-11-30T21:40:11.849220+00:00?end_time=2024-12-30T21%3A40%3A11.849220%2B00%3A00&filter_entity_id=sensor.abc_consumo_ativo_total (Caused by ConnectTimeoutError(<urllib3.connection.HTTPConnection object at 0x7fbddeca9f10>, 'Connection to 192.168.1.110 timed out. (connect timeout=10)'))
[2025-02-28T21:40:51.899+0000] {logging_mixin.py:190} INFO - ‚ùå Erro de conex√£o: HTTPConnectionPool(host='192.168.1.110', port=8123): Max retries exceeded with url: /api/history/period/2024-10-31T21:40:11.849219+00:00?end_time=2024-11-30T21%3A40%3A11.849219%2B00%3A00&filter_entity_id=sensor.abc_consumo_ativo_total (Caused by ConnectTimeoutError(<urllib3.connection.HTTPConnection object at 0x7fbddecaa6f0>, 'Connection to 192.168.1.110 timed out. (connect timeout=10)'))
[2025-02-28T21:41:01.914+0000] {logging_mixin.py:190} INFO - ‚ùå Erro de conex√£o: HTTPConnectionPool(host='192.168.1.110', port=8123): Max retries exceeded with url: /api/history/period/2024-10-01T21:40:11.849218+00:00?end_time=2024-10-31T21%3A40%3A11.849218%2B00%3A00&filter_entity_id=sensor.abc_consumo_ativo_total (Caused by ConnectTimeoutError(<urllib3.connection.HTTPConnection object at 0x7fbddecaae10>, 'Connection to 192.168.1.110 timed out. (connect timeout=10)'))
[2025-02-28T21:41:11.926+0000] {logging_mixin.py:190} INFO - ‚ùå Erro de conex√£o: HTTPConnectionPool(host='192.168.1.110', port=8123): Max retries exceeded with url: /api/history/period/2024-09-01T21:40:11.849217+00:00?end_time=2024-10-01T21%3A40%3A11.849217%2B00%3A00&filter_entity_id=sensor.abc_consumo_ativo_total (Caused by ConnectTimeoutError(<urllib3.connection.HTTPConnection object at 0x7fbddecab350>, 'Connection to 192.168.1.110 timed out. (connect timeout=10)'))
[2025-02-28T21:41:21.942+0000] {logging_mixin.py:190} INFO - ‚ùå Erro de conex√£o: HTTPConnectionPool(host='192.168.1.110', port=8123): Max retries exceeded with url: /api/history/period/2024-08-02T21:40:11.849216+00:00?end_time=2024-09-01T21%3A40%3A11.849216%2B00%3A00&filter_entity_id=sensor.abc_consumo_ativo_total (Caused by ConnectTimeoutError(<urllib3.connection.HTTPConnection object at 0x7fbddecab350>, 'Connection to 192.168.1.110 timed out. (connect timeout=10)'))
[2025-02-28T21:41:31.955+0000] {logging_mixin.py:190} INFO - ‚ùå Erro de conex√£o: HTTPConnectionPool(host='192.168.1.110', port=8123): Max retries exceeded with url: /api/history/period/2024-07-03T21:40:11.849215+00:00?end_time=2024-08-02T21%3A40%3A11.849215%2B00%3A00&filter_entity_id=sensor.abc_consumo_ativo_total (Caused by ConnectTimeoutError(<urllib3.connection.HTTPConnection object at 0x7fbddecaa990>, 'Connection to 192.168.1.110 timed out. (connect timeout=10)'))
[2025-02-28T21:41:41.968+0000] {logging_mixin.py:190} INFO - ‚ùå Erro de conex√£o: HTTPConnectionPool(host='192.168.1.110', port=8123): Max retries exceeded with url: /api/history/period/2024-06-03T21:40:11.849214+00:00?end_time=2024-07-03T21%3A40%3A11.849214%2B00%3A00&filter_entity_id=sensor.abc_consumo_ativo_total (Caused by ConnectTimeoutError(<urllib3.connection.HTTPConnection object at 0x7fbddeca9b20>, 'Connection to 192.168.1.110 timed out. (connect timeout=10)'))
[2025-02-28T21:41:51.983+0000] {logging_mixin.py:190} INFO - ‚ùå Erro de conex√£o: HTTPConnectionPool(host='192.168.1.110', port=8123): Max retries exceeded with url: /api/history/period/2024-05-04T21:40:11.849213+00:00?end_time=2024-06-03T21%3A40%3A11.849213%2B00%3A00&filter_entity_id=sensor.abc_consumo_ativo_total (Caused by ConnectTimeoutError(<urllib3.connection.HTTPConnection object at 0x7fbddeca9640>, 'Connection to 192.168.1.110 timed out. (connect timeout=10)'))
[2025-02-28T21:42:01.998+0000] {logging_mixin.py:190} INFO - ‚ùå Erro de conex√£o: HTTPConnectionPool(host='192.168.1.110', port=8123): Max retries exceeded with url: /api/history/period/2024-04-04T21:40:11.849212+00:00?end_time=2024-05-04T21%3A40%3A11.849212%2B00%3A00&filter_entity_id=sensor.abc_consumo_ativo_total (Caused by ConnectTimeoutError(<urllib3.connection.HTTPConnection object at 0x7fbddecd4530>, 'Connection to 192.168.1.110 timed out. (connect timeout=10)'))
[2025-02-28T21:42:12.009+0000] {logging_mixin.py:190} INFO - ‚ùå Erro de conex√£o: HTTPConnectionPool(host='192.168.1.110', port=8123): Max retries exceeded with url: /api/history/period/2024-03-05T21:40:11.849211+00:00?end_time=2024-04-04T21%3A40%3A11.849211%2B00%3A00&filter_entity_id=sensor.abc_consumo_ativo_total (Caused by ConnectTimeoutError(<urllib3.connection.HTTPConnection object at 0x7fbddecd4fb0>, 'Connection to 192.168.1.110 timed out. (connect timeout=10)'))
[2025-02-28T21:42:22.025+0000] {logging_mixin.py:190} INFO - ‚ùå Erro de conex√£o: HTTPConnectionPool(host='192.168.1.110', port=8123): Max retries exceeded with url: /api/history/period/2024-02-04T21:40:11.849210+00:00?end_time=2024-03-05T21%3A40%3A11.849210%2B00%3A00&filter_entity_id=sensor.abc_consumo_ativo_total (Caused by ConnectTimeoutError(<urllib3.connection.HTTPConnection object at 0x7fbdded02210>, 'Connection to 192.168.1.110 timed out. (connect timeout=10)'))
[2025-02-28T21:42:32.039+0000] {logging_mixin.py:190} INFO - ‚ùå Erro de conex√£o: HTTPConnectionPool(host='192.168.1.110', port=8123): Max retries exceeded with url: /api/history/period/2024-01-05T21:40:11.849209+00:00?end_time=2024-02-04T21%3A40%3A11.849209%2B00%3A00&filter_entity_id=sensor.abc_consumo_ativo_total (Caused by ConnectTimeoutError(<urllib3.connection.HTTPConnection object at 0x7fbddeca9370>, 'Connection to 192.168.1.110 timed out. (connect timeout=10)'))
[2025-02-28T21:42:42.043+0000] {logging_mixin.py:190} INFO - ‚ùå Erro de conex√£o: HTTPConnectionPool(host='192.168.1.110', port=8123): Max retries exceeded with url: /api/history/period/2023-12-06T21:40:11.849208+00:00?end_time=2024-01-05T21%3A40%3A11.849208%2B00%3A00&filter_entity_id=sensor.abc_consumo_ativo_total (Caused by ConnectTimeoutError(<urllib3.connection.HTTPConnection object at 0x7fbddecab050>, 'Connection to 192.168.1.110 timed out. (connect timeout=10)'))
[2025-02-28T21:42:52.053+0000] {logging_mixin.py:190} INFO - ‚ùå Erro de conex√£o: HTTPConnectionPool(host='192.168.1.110', port=8123): Max retries exceeded with url: /api/history/period/2023-11-06T21:40:11.849207+00:00?end_time=2023-12-06T21%3A40%3A11.849207%2B00%3A00&filter_entity_id=sensor.abc_consumo_ativo_total (Caused by ConnectTimeoutError(<urllib3.connection.HTTPConnection object at 0x7fbddecab3e0>, 'Connection to 192.168.1.110 timed out. (connect timeout=10)'))
[2025-02-28T21:43:02.066+0000] {logging_mixin.py:190} INFO - ‚ùå Erro de conex√£o: HTTPConnectionPool(host='192.168.1.110', port=8123): Max retries exceeded with url: /api/history/period/2023-10-07T21:40:11.849206+00:00?end_time=2023-11-06T21%3A40%3A11.849206%2B00%3A00&filter_entity_id=sensor.abc_consumo_ativo_total (Caused by ConnectTimeoutError(<urllib3.connection.HTTPConnection object at 0x7fbddecd49e0>, 'Connection to 192.168.1.110 timed out. (connect timeout=10)'))
[2025-02-28T21:43:12.077+0000] {logging_mixin.py:190} INFO - ‚ùå Erro de conex√£o: HTTPConnectionPool(host='192.168.1.110', port=8123): Max retries exceeded with url: /api/history/period/2023-09-07T21:40:11.849205+00:00?end_time=2023-10-07T21%3A40%3A11.849205%2B00%3A00&filter_entity_id=sensor.abc_consumo_ativo_total (Caused by ConnectTimeoutError(<urllib3.connection.HTTPConnection object at 0x7fbddecd4620>, 'Connection to 192.168.1.110 timed out. (connect timeout=10)'))
[2025-02-28T21:43:22.094+0000] {logging_mixin.py:190} INFO - ‚ùå Erro de conex√£o: HTTPConnectionPool(host='192.168.1.110', port=8123): Max retries exceeded with url: /api/history/period/2023-08-08T21:40:11.849204+00:00?end_time=2023-09-07T21%3A40%3A11.849204%2B00%3A00&filter_entity_id=sensor.abc_consumo_ativo_total (Caused by ConnectTimeoutError(<urllib3.connection.HTTPConnection object at 0x7fbddecab890>, 'Connection to 192.168.1.110 timed out. (connect timeout=10)'))
[2025-02-28T21:43:32.109+0000] {logging_mixin.py:190} INFO - ‚ùå Erro de conex√£o: HTTPConnectionPool(host='192.168.1.110', port=8123): Max retries exceeded with url: /api/history/period/2023-07-09T21:40:11.849203+00:00?end_time=2023-08-08T21%3A40%3A11.849203%2B00%3A00&filter_entity_id=sensor.abc_consumo_ativo_total (Caused by ConnectTimeoutError(<urllib3.connection.HTTPConnection object at 0x7fbddecaaa50>, 'Connection to 192.168.1.110 timed out. (connect timeout=10)'))
[2025-02-28T21:43:42.123+0000] {logging_mixin.py:190} INFO - ‚ùå Erro de conex√£o: HTTPConnectionPool(host='192.168.1.110', port=8123): Max retries exceeded with url: /api/history/period/2023-06-09T21:40:11.849202+00:00?end_time=2023-07-09T21%3A40%3A11.849202%2B00%3A00&filter_entity_id=sensor.abc_consumo_ativo_total (Caused by ConnectTimeoutError(<urllib3.connection.HTTPConnection object at 0x7fbddeca9160>, 'Connection to 192.168.1.110 timed out. (connect timeout=10)'))
[2025-02-28T21:43:52.138+0000] {logging_mixin.py:190} INFO - ‚ùå Erro de conex√£o: HTTPConnectionPool(host='192.168.1.110', port=8123): Max retries exceeded with url: /api/history/period/2023-05-10T21:40:11.849201+00:00?end_time=2023-06-09T21%3A40%3A11.849201%2B00%3A00&filter_entity_id=sensor.abc_consumo_ativo_total (Caused by ConnectTimeoutError(<urllib3.connection.HTTPConnection object at 0x7fbddec3daf0>, 'Connection to 192.168.1.110 timed out. (connect timeout=10)'))
[2025-02-28T21:44:02.153+0000] {logging_mixin.py:190} INFO - ‚ùå Erro de conex√£o: HTTPConnectionPool(host='192.168.1.110', port=8123): Max retries exceeded with url: /api/history/period/2023-04-10T21:40:11.849200+00:00?end_time=2023-05-10T21%3A40%3A11.849200%2B00%3A00&filter_entity_id=sensor.abc_consumo_ativo_total (Caused by ConnectTimeoutError(<urllib3.connection.HTTPConnection object at 0x7fbddecd4b60>, 'Connection to 192.168.1.110 timed out. (connect timeout=10)'))
[2025-02-28T21:44:12.158+0000] {logging_mixin.py:190} INFO - ‚ùå Erro de conex√£o: HTTPConnectionPool(host='192.168.1.110', port=8123): Max retries exceeded with url: /api/history/period/2023-03-11T21:40:11.849199+00:00?end_time=2023-04-10T21%3A40%3A11.849199%2B00%3A00&filter_entity_id=sensor.abc_consumo_ativo_total (Caused by ConnectTimeoutError(<urllib3.connection.HTTPConnection object at 0x7fbddecd4770>, 'Connection to 192.168.1.110 timed out. (connect timeout=10)'))
[2025-02-28T21:44:22.174+0000] {logging_mixin.py:190} INFO - ‚ùå Erro de conex√£o: HTTPConnectionPool(host='192.168.1.110', port=8123): Max retries exceeded with url: /api/history/period/2023-02-09T21:40:11.849198+00:00?end_time=2023-03-11T21%3A40%3A11.849198%2B00%3A00&filter_entity_id=sensor.abc_consumo_ativo_total (Caused by ConnectTimeoutError(<urllib3.connection.HTTPConnection object at 0x7fbddec3daf0>, 'Connection to 192.168.1.110 timed out. (connect timeout=10)'))
[2025-02-28T21:44:32.189+0000] {logging_mixin.py:190} INFO - ‚ùå Erro de conex√£o: HTTPConnectionPool(host='192.168.1.110', port=8123): Max retries exceeded with url: /api/history/period/2023-01-10T21:40:11.849197+00:00?end_time=2023-02-09T21%3A40%3A11.849197%2B00%3A00&filter_entity_id=sensor.abc_consumo_ativo_total (Caused by ConnectTimeoutError(<urllib3.connection.HTTPConnection object at 0x7fbddeca99a0>, 'Connection to 192.168.1.110 timed out. (connect timeout=10)'))
[2025-02-28T21:44:42.196+0000] {logging_mixin.py:190} INFO - ‚ùå Erro de conex√£o: HTTPConnectionPool(host='192.168.1.110', port=8123): Max retries exceeded with url: /api/history/period/2022-12-11T21:40:11.849196+00:00?end_time=2023-01-10T21%3A40%3A11.849196%2B00%3A00&filter_entity_id=sensor.abc_consumo_ativo_total (Caused by ConnectTimeoutError(<urllib3.connection.HTTPConnection object at 0x7fbddecaa5a0>, 'Connection to 192.168.1.110 timed out. (connect timeout=10)'))
[2025-02-28T21:44:52.211+0000] {logging_mixin.py:190} INFO - ‚ùå Erro de conex√£o: HTTPConnectionPool(host='192.168.1.110', port=8123): Max retries exceeded with url: /api/history/period/2022-11-11T21:40:11.849195+00:00?end_time=2022-12-11T21%3A40%3A11.849195%2B00%3A00&filter_entity_id=sensor.abc_consumo_ativo_total (Caused by ConnectTimeoutError(<urllib3.connection.HTTPConnection object at 0x7fbddeca8ce0>, 'Connection to 192.168.1.110 timed out. (connect timeout=10)'))
[2025-02-28T21:45:02.224+0000] {logging_mixin.py:190} INFO - ‚ùå Erro de conex√£o: HTTPConnectionPool(host='192.168.1.110', port=8123): Max retries exceeded with url: /api/history/period/2022-10-12T21:40:11.849194+00:00?end_time=2022-11-11T21%3A40%3A11.849194%2B00%3A00&filter_entity_id=sensor.abc_consumo_ativo_total (Caused by ConnectTimeoutError(<urllib3.connection.HTTPConnection object at 0x7fbddecd5130>, 'Connection to 192.168.1.110 timed out. (connect timeout=10)'))
[2025-02-28T21:45:12.236+0000] {logging_mixin.py:190} INFO - ‚ùå Erro de conex√£o: HTTPConnectionPool(host='192.168.1.110', port=8123): Max retries exceeded with url: /api/history/period/2022-09-12T21:40:11.849193+00:00?end_time=2022-10-12T21%3A40%3A11.849193%2B00%3A00&filter_entity_id=sensor.abc_consumo_ativo_total (Caused by ConnectTimeoutError(<urllib3.connection.HTTPConnection object at 0x7fbddecd43b0>, 'Connection to 192.168.1.110 timed out. (connect timeout=10)'))
[2025-02-28T21:45:22.252+0000] {logging_mixin.py:190} INFO - ‚ùå Erro de conex√£o: HTTPConnectionPool(host='192.168.1.110', port=8123): Max retries exceeded with url: /api/history/period/2022-08-13T21:40:11.849192+00:00?end_time=2022-09-12T21%3A40%3A11.849192%2B00%3A00&filter_entity_id=sensor.abc_consumo_ativo_total (Caused by ConnectTimeoutError(<urllib3.connection.HTTPConnection object at 0x7fbddecd6570>, 'Connection to 192.168.1.110 timed out. (connect timeout=10)'))
[2025-02-28T21:45:32.265+0000] {logging_mixin.py:190} INFO - ‚ùå Erro de conex√£o: HTTPConnectionPool(host='192.168.1.110', port=8123): Max retries exceeded with url: /api/history/period/2022-07-14T21:40:11.849191+00:00?end_time=2022-08-13T21%3A40%3A11.849191%2B00%3A00&filter_entity_id=sensor.abc_consumo_ativo_total (Caused by ConnectTimeoutError(<urllib3.connection.HTTPConnection object at 0x7fbddeca8f50>, 'Connection to 192.168.1.110 timed out. (connect timeout=10)'))
[2025-02-28T21:45:42.273+0000] {logging_mixin.py:190} INFO - ‚ùå Erro de conex√£o: HTTPConnectionPool(host='192.168.1.110', port=8123): Max retries exceeded with url: /api/history/period/2022-06-14T21:40:11.849190+00:00?end_time=2022-07-14T21%3A40%3A11.849190%2B00%3A00&filter_entity_id=sensor.abc_consumo_ativo_total (Caused by ConnectTimeoutError(<urllib3.connection.HTTPConnection object at 0x7fbddecab170>, 'Connection to 192.168.1.110 timed out. (connect timeout=10)'))
[2025-02-28T21:45:52.285+0000] {logging_mixin.py:190} INFO - ‚ùå Erro de conex√£o: HTTPConnectionPool(host='192.168.1.110', port=8123): Max retries exceeded with url: /api/history/period/2022-06-04T21:40:11.849224+00:00?end_time=2022-06-14T21%3A40%3A11.849189%2B00%3A00&filter_entity_id=sensor.abc_consumo_ativo_total (Caused by ConnectTimeoutError(<urllib3.connection.HTTPConnection object at 0x7fbddec3caa0>, 'Connection to 192.168.1.110 timed out. (connect timeout=10)'))
[2025-02-28T21:45:52.285+0000] {logging_mixin.py:190} INFO - ‚ö†Ô∏è Nenhum dado hist√≥rico encontrado para sensor.abc_consumo_ativo_total
[2025-02-28T21:45:52.286+0000] {logging_mixin.py:190} INFO - ‚ùå Erro na extra√ß√£o dos dados: ‚ùå Nenhum dado encontrado para sensor.abc_consumo_ativo_total
[2025-02-28T21:45:52.287+0000] {taskinstance.py:3313} ERROR - Task failed with exception
Traceback (most recent call last):
  File "/home/airflow/.local/lib/python3.12/site-packages/airflow/models/taskinstance.py", line 768, in _execute_task
    result = _execute_callable(context=context, **execute_callable_kwargs)
             ^^^^^^^^^^^^^^^^^^^^^^^^^^^^^^^^^^^^^^^^^^^^^^^^^^^^^^^^^^^^^
  File "/home/airflow/.local/lib/python3.12/site-packages/airflow/models/taskinstance.py", line 734, in _execute_callable
    return ExecutionCallableRunner(
           ^^^^^^^^^^^^^^^^^^^^^^^^
  File "/home/airflow/.local/lib/python3.12/site-packages/airflow/utils/operator_helpers.py", line 252, in run
    return self.func(*args, **kwargs)
           ^^^^^^^^^^^^^^^^^^^^^^^^^^
  File "/home/airflow/.local/lib/python3.12/site-packages/airflow/models/baseoperator.py", line 424, in wrapper
    return func(self, *args, **kwargs)
           ^^^^^^^^^^^^^^^^^^^^^^^^^^^
  File "/home/airflow/.local/lib/python3.12/site-packages/airflow/operators/python.py", line 238, in execute
    return_value = self.execute_callable()
                   ^^^^^^^^^^^^^^^^^^^^^^^
  File "/home/airflow/.local/lib/python3.12/site-packages/airflow/operators/python.py", line 256, in execute_callable
    return runner.run(*self.op_args, **self.op_kwargs)
           ^^^^^^^^^^^^^^^^^^^^^^^^^^^^^^^^^^^^^^^^^^^
  File "/home/airflow/.local/lib/python3.12/site-packages/airflow/utils/operator_helpers.py", line 252, in run
    return self.func(*args, **kwargs)
           ^^^^^^^^^^^^^^^^^^^^^^^^^^
  File "/opt/airflow/dags/ha_etl_process.py", line 110, in extract_data
    raise ValueError(f"‚ùå Nenhum dado encontrado para {entity_consumo_mes}")
ValueError: ‚ùå Nenhum dado encontrado para sensor.abc_consumo_ativo_total
[2025-02-28T21:45:52.307+0000] {logging_mixin.py:190} INFO - Task instance in failure state
[2025-02-28T21:45:52.307+0000] {logging_mixin.py:190} INFO - Task start:2025-02-28 21:40:11.671154+00:00 end:2025-02-28 21:45:52.306729+00:00 duration:340.635575
[2025-02-28T21:45:52.308+0000] {logging_mixin.py:190} INFO - Task:<Task(PythonOperator): extract_task> dag:<DAG: ha_etl_process> dagrun:<DagRun ha_etl_process @ 2025-02-28 21:40:09.515454+00:00: manual__2025-02-28T21:40:09.515454+00:00, state:running, queued_at: 2025-02-28 21:40:09.545517+00:00. externally triggered: True>
[2025-02-28T21:45:52.308+0000] {logging_mixin.py:190} INFO - Failure caused by ‚ùå Nenhum dado encontrado para sensor.abc_consumo_ativo_total
[2025-02-28T21:45:52.309+0000] {taskinstance.py:1226} INFO - Marking task as UP_FOR_RETRY. dag_id=ha_etl_process, task_id=extract_task, run_id=manual__2025-02-28T21:40:09.515454+00:00, execution_date=20250228T214009, start_date=20250228T214011, end_date=20250228T214552
[2025-02-28T21:45:52.348+0000] {taskinstance.py:341} INFO - ::group::Post task execution logs
[2025-02-28T21:45:52.349+0000] {standard_task_runner.py:124} ERROR - Failed to execute job 131 for task extract_task (‚ùå Nenhum dado encontrado para sensor.abc_consumo_ativo_total; 802)
Traceback (most recent call last):
  File "/home/airflow/.local/lib/python3.12/site-packages/airflow/task/task_runner/standard_task_runner.py", line 117, in _start_by_fork
    ret = args.func(args, dag=self.dag)
          ^^^^^^^^^^^^^^^^^^^^^^^^^^^^^
  File "/home/airflow/.local/lib/python3.12/site-packages/airflow/cli/cli_config.py", line 49, in command
    return func(*args, **kwargs)
           ^^^^^^^^^^^^^^^^^^^^^
  File "/home/airflow/.local/lib/python3.12/site-packages/airflow/utils/cli.py", line 116, in wrapper
    return f(*args, **kwargs)
           ^^^^^^^^^^^^^^^^^^
  File "/home/airflow/.local/lib/python3.12/site-packages/airflow/cli/commands/task_command.py", line 483, in task_run
    task_return_code = _run_task_by_selected_method(args, _dag, ti)
                       ^^^^^^^^^^^^^^^^^^^^^^^^^^^^^^^^^^^^^^^^^^^^
  File "/home/airflow/.local/lib/python3.12/site-packages/airflow/cli/commands/task_command.py", line 256, in _run_task_by_selected_method
    return _run_raw_task(args, ti)
           ^^^^^^^^^^^^^^^^^^^^^^^
  File "/home/airflow/.local/lib/python3.12/site-packages/airflow/cli/commands/task_command.py", line 341, in _run_raw_task
    return ti._run_raw_task(
           ^^^^^^^^^^^^^^^^^
  File "/home/airflow/.local/lib/python3.12/site-packages/airflow/utils/session.py", line 97, in wrapper
    return func(*args, session=session, **kwargs)
           ^^^^^^^^^^^^^^^^^^^^^^^^^^^^^^^^^^^^^^
  File "/home/airflow/.local/lib/python3.12/site-packages/airflow/models/taskinstance.py", line 3006, in _run_raw_task
    return _run_raw_task(
           ^^^^^^^^^^^^^^
  File "/home/airflow/.local/lib/python3.12/site-packages/airflow/models/taskinstance.py", line 274, in _run_raw_task
    TaskInstance._execute_task_with_callbacks(
  File "/home/airflow/.local/lib/python3.12/site-packages/airflow/models/taskinstance.py", line 3161, in _execute_task_with_callbacks
    result = self._execute_task(context, task_orig)
             ^^^^^^^^^^^^^^^^^^^^^^^^^^^^^^^^^^^^^^
  File "/home/airflow/.local/lib/python3.12/site-packages/airflow/models/taskinstance.py", line 3185, in _execute_task
    return _execute_task(self, context, task_orig)
           ^^^^^^^^^^^^^^^^^^^^^^^^^^^^^^^^^^^^^^^
  File "/home/airflow/.local/lib/python3.12/site-packages/airflow/models/taskinstance.py", line 768, in _execute_task
    result = _execute_callable(context=context, **execute_callable_kwargs)
             ^^^^^^^^^^^^^^^^^^^^^^^^^^^^^^^^^^^^^^^^^^^^^^^^^^^^^^^^^^^^^
  File "/home/airflow/.local/lib/python3.12/site-packages/airflow/models/taskinstance.py", line 734, in _execute_callable
    return ExecutionCallableRunner(
           ^^^^^^^^^^^^^^^^^^^^^^^^
  File "/home/airflow/.local/lib/python3.12/site-packages/airflow/utils/operator_helpers.py", line 252, in run
    return self.func(*args, **kwargs)
           ^^^^^^^^^^^^^^^^^^^^^^^^^^
  File "/home/airflow/.local/lib/python3.12/site-packages/airflow/models/baseoperator.py", line 424, in wrapper
    return func(self, *args, **kwargs)
           ^^^^^^^^^^^^^^^^^^^^^^^^^^^
  File "/home/airflow/.local/lib/python3.12/site-packages/airflow/operators/python.py", line 238, in execute
    return_value = self.execute_callable()
                   ^^^^^^^^^^^^^^^^^^^^^^^
  File "/home/airflow/.local/lib/python3.12/site-packages/airflow/operators/python.py", line 256, in execute_callable
    return runner.run(*self.op_args, **self.op_kwargs)
           ^^^^^^^^^^^^^^^^^^^^^^^^^^^^^^^^^^^^^^^^^^^
  File "/home/airflow/.local/lib/python3.12/site-packages/airflow/utils/operator_helpers.py", line 252, in run
    return self.func(*args, **kwargs)
           ^^^^^^^^^^^^^^^^^^^^^^^^^^
  File "/opt/airflow/dags/ha_etl_process.py", line 110, in extract_data
    raise ValueError(f"‚ùå Nenhum dado encontrado para {entity_consumo_mes}")
ValueError: ‚ùå Nenhum dado encontrado para sensor.abc_consumo_ativo_total
[2025-02-28T21:45:52.384+0000] {local_task_job_runner.py:266} INFO - Task exited with return code 1
[2025-02-28T21:45:52.416+0000] {taskinstance.py:3901} INFO - 0 downstream tasks scheduled from follow-on schedule check
[2025-02-28T21:45:52.419+0000] {local_task_job_runner.py:245} INFO - ::endgroup::
