[2025-02-28T22:04:41.888+0000] {local_task_job_runner.py:123} INFO - ::group::Pre task execution logs
[2025-02-28T22:04:41.906+0000] {taskinstance.py:2614} INFO - Dependencies all met for dep_context=non-requeueable deps ti=<TaskInstance: ha_etl_process.extract_task manual__2025-02-28T22:04:40.382827+00:00 [queued]>
[2025-02-28T22:04:41.914+0000] {taskinstance.py:2614} INFO - Dependencies all met for dep_context=requeueable deps ti=<TaskInstance: ha_etl_process.extract_task manual__2025-02-28T22:04:40.382827+00:00 [queued]>
[2025-02-28T22:04:41.915+0000] {taskinstance.py:2867} INFO - Starting attempt 1 of 2
[2025-02-28T22:04:41.930+0000] {taskinstance.py:2890} INFO - Executing <Task(PythonOperator): extract_task> on 2025-02-28 22:04:40.382827+00:00
[2025-02-28T22:04:41.939+0000] {standard_task_runner.py:104} INFO - Running: ['***', 'tasks', 'run', 'ha_etl_process', 'extract_task', 'manual__2025-02-28T22:04:40.382827+00:00', '--job-id', '146', '--raw', '--subdir', 'DAGS_FOLDER/ha_etl_process.py', '--cfg-path', '/tmp/tmpcpze8opk']
[2025-02-28T22:04:41.941+0000] {standard_task_runner.py:105} INFO - Job 146: Subtask extract_task
[2025-02-28T22:04:41.943+0000] {logging_mixin.py:190} WARNING - /home/***/.local/lib/python3.12/site-packages/***/task/task_runner/standard_task_runner.py:70 DeprecationWarning: This process (pid=497) is multi-threaded, use of fork() may lead to deadlocks in the child.
[2025-02-28T22:04:41.944+0000] {standard_task_runner.py:72} INFO - Started process 498 to run task
[2025-02-28T22:04:42.006+0000] {task_command.py:467} INFO - Running <TaskInstance: ha_etl_process.extract_task manual__2025-02-28T22:04:40.382827+00:00 [running]> on host 151d4861bf1b
[2025-02-28T22:04:42.096+0000] {taskinstance.py:3134} INFO - Exporting env vars: AIRFLOW_CTX_DAG_OWNER='***' AIRFLOW_CTX_DAG_ID='ha_etl_process' AIRFLOW_CTX_TASK_ID='extract_task' AIRFLOW_CTX_EXECUTION_DATE='2025-02-28T22:04:40.382827+00:00' AIRFLOW_CTX_TRY_NUMBER='1' AIRFLOW_CTX_DAG_RUN_ID='manual__2025-02-28T22:04:40.382827+00:00'
[2025-02-28T22:04:42.098+0000] {logging_mixin.py:190} INFO - Task instance is in running state
[2025-02-28T22:04:42.098+0000] {logging_mixin.py:190} INFO -  Previous state of the Task instance: queued
[2025-02-28T22:04:42.099+0000] {logging_mixin.py:190} INFO - Current task name:extract_task state:running start_date:2025-02-28 22:04:41.907034+00:00
[2025-02-28T22:04:42.099+0000] {logging_mixin.py:190} INFO - Dag name:ha_etl_process and current dag run status:running
[2025-02-28T22:04:42.100+0000] {taskinstance.py:732} INFO - ::endgroup::
[2025-02-28T22:04:42.101+0000] {logging_mixin.py:190} INFO - üîç Tentando se conectar ao Home Assistant...
[2025-02-28T22:04:42.102+0000] {logging_mixin.py:190} INFO - 
Testing API connection...
[2025-02-28T22:05:03.160+0000] {logging_mixin.py:190} INFO - Error: HTTPConnectionPool(host='192.168.1.110', port=8123): Max retries exceeded with url: /api/states (Caused by NewConnectionError('<urllib3.connection.HTTPConnection object at 0x7fd8211ce360>: Failed to establish a new connection: [Errno 111] Connection refused'))
[2025-02-28T22:05:03.161+0000] {logging_mixin.py:190} INFO - <unusual_prefix_8f7033247fce1c2ce5759715b0045e7a21193f9c_ha_etl_process.HomeAssistantAPI object at 0x7fd821076c30>
[2025-02-28T22:05:24.216+0000] {logging_mixin.py:190} INFO - ‚ùå Erro na extra√ß√£o dos dados: HTTPConnectionPool(host='192.168.1.110', port=8123): Max retries exceeded with url: /api/states (Caused by NewConnectionError('<urllib3.connection.HTTPConnection object at 0x7fd8210a4620>: Failed to establish a new connection: [Errno 111] Connection refused'))
[2025-02-28T22:05:24.217+0000] {taskinstance.py:3313} ERROR - Task failed with exception
Traceback (most recent call last):
  File "/home/airflow/.local/lib/python3.12/site-packages/urllib3/connection.py", line 198, in _new_conn
    sock = connection.create_connection(
           ^^^^^^^^^^^^^^^^^^^^^^^^^^^^^
  File "/home/airflow/.local/lib/python3.12/site-packages/urllib3/util/connection.py", line 85, in create_connection
    raise err
  File "/home/airflow/.local/lib/python3.12/site-packages/urllib3/util/connection.py", line 73, in create_connection
    sock.connect(sa)
ConnectionRefusedError: [Errno 111] Connection refused

The above exception was the direct cause of the following exception:

Traceback (most recent call last):
  File "/home/airflow/.local/lib/python3.12/site-packages/urllib3/connectionpool.py", line 787, in urlopen
    response = self._make_request(
               ^^^^^^^^^^^^^^^^^^^
  File "/home/airflow/.local/lib/python3.12/site-packages/urllib3/connectionpool.py", line 493, in _make_request
    conn.request(
  File "/home/airflow/.local/lib/python3.12/site-packages/urllib3/connection.py", line 445, in request
    self.endheaders()
  File "/usr/local/lib/python3.12/http/client.py", line 1333, in endheaders
    self._send_output(message_body, encode_chunked=encode_chunked)
  File "/usr/local/lib/python3.12/http/client.py", line 1093, in _send_output
    self.send(msg)
  File "/usr/local/lib/python3.12/http/client.py", line 1037, in send
    self.connect()
  File "/home/airflow/.local/lib/python3.12/site-packages/urllib3/connection.py", line 276, in connect
    self.sock = self._new_conn()
                ^^^^^^^^^^^^^^^^
  File "/home/airflow/.local/lib/python3.12/site-packages/urllib3/connection.py", line 213, in _new_conn
    raise NewConnectionError(
urllib3.exceptions.NewConnectionError: <urllib3.connection.HTTPConnection object at 0x7fd8210a4620>: Failed to establish a new connection: [Errno 111] Connection refused

The above exception was the direct cause of the following exception:

Traceback (most recent call last):
  File "/home/airflow/.local/lib/python3.12/site-packages/requests/adapters.py", line 667, in send
    resp = conn.urlopen(
           ^^^^^^^^^^^^^
  File "/home/airflow/.local/lib/python3.12/site-packages/urllib3/connectionpool.py", line 841, in urlopen
    retries = retries.increment(
              ^^^^^^^^^^^^^^^^^^
  File "/home/airflow/.local/lib/python3.12/site-packages/urllib3/util/retry.py", line 519, in increment
    raise MaxRetryError(_pool, url, reason) from reason  # type: ignore[arg-type]
    ^^^^^^^^^^^^^^^^^^^^^^^^^^^^^^^^^^^^^^^^^^^^^^^^^^^
urllib3.exceptions.MaxRetryError: HTTPConnectionPool(host='192.168.1.110', port=8123): Max retries exceeded with url: /api/states (Caused by NewConnectionError('<urllib3.connection.HTTPConnection object at 0x7fd8210a4620>: Failed to establish a new connection: [Errno 111] Connection refused'))

During handling of the above exception, another exception occurred:

Traceback (most recent call last):
  File "/home/airflow/.local/lib/python3.12/site-packages/airflow/models/taskinstance.py", line 768, in _execute_task
    result = _execute_callable(context=context, **execute_callable_kwargs)
             ^^^^^^^^^^^^^^^^^^^^^^^^^^^^^^^^^^^^^^^^^^^^^^^^^^^^^^^^^^^^^
  File "/home/airflow/.local/lib/python3.12/site-packages/airflow/models/taskinstance.py", line 734, in _execute_callable
    return ExecutionCallableRunner(
           ^^^^^^^^^^^^^^^^^^^^^^^^
  File "/home/airflow/.local/lib/python3.12/site-packages/airflow/utils/operator_helpers.py", line 252, in run
    return self.func(*args, **kwargs)
           ^^^^^^^^^^^^^^^^^^^^^^^^^^
  File "/home/airflow/.local/lib/python3.12/site-packages/airflow/models/baseoperator.py", line 424, in wrapper
    return func(self, *args, **kwargs)
           ^^^^^^^^^^^^^^^^^^^^^^^^^^^
  File "/home/airflow/.local/lib/python3.12/site-packages/airflow/operators/python.py", line 238, in execute
    return_value = self.execute_callable()
                   ^^^^^^^^^^^^^^^^^^^^^^^
  File "/home/airflow/.local/lib/python3.12/site-packages/airflow/operators/python.py", line 256, in execute_callable
    return runner.run(*self.op_args, **self.op_kwargs)
           ^^^^^^^^^^^^^^^^^^^^^^^^^^^^^^^^^^^^^^^^^^^
  File "/home/airflow/.local/lib/python3.12/site-packages/airflow/utils/operator_helpers.py", line 252, in run
    return self.func(*args, **kwargs)
           ^^^^^^^^^^^^^^^^^^^^^^^^^^
  File "/opt/airflow/dags/ha_etl_process.py", line 130, in extract_data
    all_states = ha.get_states()
                 ^^^^^^^^^^^^^^^
  File "/opt/airflow/dags/ha_etl_process.py", line 95, in get_states
    response = requests.get(f"{self.base_url}states", headers=self.headers)
               ^^^^^^^^^^^^^^^^^^^^^^^^^^^^^^^^^^^^^^^^^^^^^^^^^^^^^^^^^^^^
  File "/home/airflow/.local/lib/python3.12/site-packages/requests/api.py", line 73, in get
    return request("get", url, params=params, **kwargs)
           ^^^^^^^^^^^^^^^^^^^^^^^^^^^^^^^^^^^^^^^^^^^^
  File "/home/airflow/.local/lib/python3.12/site-packages/requests/api.py", line 59, in request
    return session.request(method=method, url=url, **kwargs)
           ^^^^^^^^^^^^^^^^^^^^^^^^^^^^^^^^^^^^^^^^^^^^^^^^^
  File "/home/airflow/.local/lib/python3.12/site-packages/requests/sessions.py", line 589, in request
    resp = self.send(prep, **send_kwargs)
           ^^^^^^^^^^^^^^^^^^^^^^^^^^^^^^
  File "/home/airflow/.local/lib/python3.12/site-packages/requests/sessions.py", line 703, in send
    r = adapter.send(request, **kwargs)
        ^^^^^^^^^^^^^^^^^^^^^^^^^^^^^^^
  File "/home/airflow/.local/lib/python3.12/site-packages/requests/adapters.py", line 700, in send
    raise ConnectionError(e, request=request)
requests.exceptions.ConnectionError: HTTPConnectionPool(host='192.168.1.110', port=8123): Max retries exceeded with url: /api/states (Caused by NewConnectionError('<urllib3.connection.HTTPConnection object at 0x7fd8210a4620>: Failed to establish a new connection: [Errno 111] Connection refused'))
[2025-02-28T22:05:24.241+0000] {logging_mixin.py:190} INFO - Task instance in failure state
[2025-02-28T22:05:24.242+0000] {logging_mixin.py:190} INFO - Task start:2025-02-28 22:04:41.907034+00:00 end:2025-02-28 22:05:24.240893+00:00 duration:42.333859
[2025-02-28T22:05:24.242+0000] {logging_mixin.py:190} INFO - Task:<Task(PythonOperator): extract_task> dag:<DAG: ha_etl_process> dagrun:<DagRun ha_etl_process @ 2025-02-28 22:04:40.382827+00:00: manual__2025-02-28T22:04:40.382827+00:00, state:running, queued_at: 2025-02-28 22:04:40.403550+00:00. externally triggered: True>
[2025-02-28T22:05:24.243+0000] {logging_mixin.py:190} INFO - Failure caused by HTTPConnectionPool(host='192.168.1.110', port=8123): Max retries exceeded with url: /api/states (Caused by NewConnectionError('<urllib3.connection.HTTPConnection object at 0x7fd8210a4620>: Failed to establish a new connection: [Errno 111] Connection refused'))
[2025-02-28T22:05:24.243+0000] {taskinstance.py:1226} INFO - Marking task as UP_FOR_RETRY. dag_id=ha_etl_process, task_id=extract_task, run_id=manual__2025-02-28T22:04:40.382827+00:00, execution_date=20250228T220440, start_date=20250228T220441, end_date=20250228T220524
[2025-02-28T22:05:24.285+0000] {taskinstance.py:341} INFO - ::group::Post task execution logs
[2025-02-28T22:05:24.286+0000] {standard_task_runner.py:124} ERROR - Failed to execute job 146 for task extract_task (HTTPConnectionPool(host='192.168.1.110', port=8123): Max retries exceeded with url: /api/states (Caused by NewConnectionError('<urllib3.connection.HTTPConnection object at 0x7fd8210a4620>: Failed to establish a new connection: [Errno 111] Connection refused')); 498)
Traceback (most recent call last):
  File "/home/airflow/.local/lib/python3.12/site-packages/urllib3/connection.py", line 198, in _new_conn
    sock = connection.create_connection(
           ^^^^^^^^^^^^^^^^^^^^^^^^^^^^^
  File "/home/airflow/.local/lib/python3.12/site-packages/urllib3/util/connection.py", line 85, in create_connection
    raise err
  File "/home/airflow/.local/lib/python3.12/site-packages/urllib3/util/connection.py", line 73, in create_connection
    sock.connect(sa)
ConnectionRefusedError: [Errno 111] Connection refused

The above exception was the direct cause of the following exception:

Traceback (most recent call last):
  File "/home/airflow/.local/lib/python3.12/site-packages/urllib3/connectionpool.py", line 787, in urlopen
    response = self._make_request(
               ^^^^^^^^^^^^^^^^^^^
  File "/home/airflow/.local/lib/python3.12/site-packages/urllib3/connectionpool.py", line 493, in _make_request
    conn.request(
  File "/home/airflow/.local/lib/python3.12/site-packages/urllib3/connection.py", line 445, in request
    self.endheaders()
  File "/usr/local/lib/python3.12/http/client.py", line 1333, in endheaders
    self._send_output(message_body, encode_chunked=encode_chunked)
  File "/usr/local/lib/python3.12/http/client.py", line 1093, in _send_output
    self.send(msg)
  File "/usr/local/lib/python3.12/http/client.py", line 1037, in send
    self.connect()
  File "/home/airflow/.local/lib/python3.12/site-packages/urllib3/connection.py", line 276, in connect
    self.sock = self._new_conn()
                ^^^^^^^^^^^^^^^^
  File "/home/airflow/.local/lib/python3.12/site-packages/urllib3/connection.py", line 213, in _new_conn
    raise NewConnectionError(
urllib3.exceptions.NewConnectionError: <urllib3.connection.HTTPConnection object at 0x7fd8210a4620>: Failed to establish a new connection: [Errno 111] Connection refused

The above exception was the direct cause of the following exception:

Traceback (most recent call last):
  File "/home/airflow/.local/lib/python3.12/site-packages/requests/adapters.py", line 667, in send
    resp = conn.urlopen(
           ^^^^^^^^^^^^^
  File "/home/airflow/.local/lib/python3.12/site-packages/urllib3/connectionpool.py", line 841, in urlopen
    retries = retries.increment(
              ^^^^^^^^^^^^^^^^^^
  File "/home/airflow/.local/lib/python3.12/site-packages/urllib3/util/retry.py", line 519, in increment
    raise MaxRetryError(_pool, url, reason) from reason  # type: ignore[arg-type]
    ^^^^^^^^^^^^^^^^^^^^^^^^^^^^^^^^^^^^^^^^^^^^^^^^^^^
urllib3.exceptions.MaxRetryError: HTTPConnectionPool(host='192.168.1.110', port=8123): Max retries exceeded with url: /api/states (Caused by NewConnectionError('<urllib3.connection.HTTPConnection object at 0x7fd8210a4620>: Failed to establish a new connection: [Errno 111] Connection refused'))

During handling of the above exception, another exception occurred:

Traceback (most recent call last):
  File "/home/airflow/.local/lib/python3.12/site-packages/airflow/task/task_runner/standard_task_runner.py", line 117, in _start_by_fork
    ret = args.func(args, dag=self.dag)
          ^^^^^^^^^^^^^^^^^^^^^^^^^^^^^
  File "/home/airflow/.local/lib/python3.12/site-packages/airflow/cli/cli_config.py", line 49, in command
    return func(*args, **kwargs)
           ^^^^^^^^^^^^^^^^^^^^^
  File "/home/airflow/.local/lib/python3.12/site-packages/airflow/utils/cli.py", line 116, in wrapper
    return f(*args, **kwargs)
           ^^^^^^^^^^^^^^^^^^
  File "/home/airflow/.local/lib/python3.12/site-packages/airflow/cli/commands/task_command.py", line 483, in task_run
    task_return_code = _run_task_by_selected_method(args, _dag, ti)
                       ^^^^^^^^^^^^^^^^^^^^^^^^^^^^^^^^^^^^^^^^^^^^
  File "/home/airflow/.local/lib/python3.12/site-packages/airflow/cli/commands/task_command.py", line 256, in _run_task_by_selected_method
    return _run_raw_task(args, ti)
           ^^^^^^^^^^^^^^^^^^^^^^^
  File "/home/airflow/.local/lib/python3.12/site-packages/airflow/cli/commands/task_command.py", line 341, in _run_raw_task
    return ti._run_raw_task(
           ^^^^^^^^^^^^^^^^^
  File "/home/airflow/.local/lib/python3.12/site-packages/airflow/utils/session.py", line 97, in wrapper
    return func(*args, session=session, **kwargs)
           ^^^^^^^^^^^^^^^^^^^^^^^^^^^^^^^^^^^^^^
  File "/home/airflow/.local/lib/python3.12/site-packages/airflow/models/taskinstance.py", line 3006, in _run_raw_task
    return _run_raw_task(
           ^^^^^^^^^^^^^^
  File "/home/airflow/.local/lib/python3.12/site-packages/airflow/models/taskinstance.py", line 274, in _run_raw_task
    TaskInstance._execute_task_with_callbacks(
  File "/home/airflow/.local/lib/python3.12/site-packages/airflow/models/taskinstance.py", line 3161, in _execute_task_with_callbacks
    result = self._execute_task(context, task_orig)
             ^^^^^^^^^^^^^^^^^^^^^^^^^^^^^^^^^^^^^^
  File "/home/airflow/.local/lib/python3.12/site-packages/airflow/models/taskinstance.py", line 3185, in _execute_task
    return _execute_task(self, context, task_orig)
           ^^^^^^^^^^^^^^^^^^^^^^^^^^^^^^^^^^^^^^^
  File "/home/airflow/.local/lib/python3.12/site-packages/airflow/models/taskinstance.py", line 768, in _execute_task
    result = _execute_callable(context=context, **execute_callable_kwargs)
             ^^^^^^^^^^^^^^^^^^^^^^^^^^^^^^^^^^^^^^^^^^^^^^^^^^^^^^^^^^^^^
  File "/home/airflow/.local/lib/python3.12/site-packages/airflow/models/taskinstance.py", line 734, in _execute_callable
    return ExecutionCallableRunner(
           ^^^^^^^^^^^^^^^^^^^^^^^^
  File "/home/airflow/.local/lib/python3.12/site-packages/airflow/utils/operator_helpers.py", line 252, in run
    return self.func(*args, **kwargs)
           ^^^^^^^^^^^^^^^^^^^^^^^^^^
  File "/home/airflow/.local/lib/python3.12/site-packages/airflow/models/baseoperator.py", line 424, in wrapper
    return func(self, *args, **kwargs)
           ^^^^^^^^^^^^^^^^^^^^^^^^^^^
  File "/home/airflow/.local/lib/python3.12/site-packages/airflow/operators/python.py", line 238, in execute
    return_value = self.execute_callable()
                   ^^^^^^^^^^^^^^^^^^^^^^^
  File "/home/airflow/.local/lib/python3.12/site-packages/airflow/operators/python.py", line 256, in execute_callable
    return runner.run(*self.op_args, **self.op_kwargs)
           ^^^^^^^^^^^^^^^^^^^^^^^^^^^^^^^^^^^^^^^^^^^
  File "/home/airflow/.local/lib/python3.12/site-packages/airflow/utils/operator_helpers.py", line 252, in run
    return self.func(*args, **kwargs)
           ^^^^^^^^^^^^^^^^^^^^^^^^^^
  File "/opt/airflow/dags/ha_etl_process.py", line 130, in extract_data
    all_states = ha.get_states()
                 ^^^^^^^^^^^^^^^
  File "/opt/airflow/dags/ha_etl_process.py", line 95, in get_states
    response = requests.get(f"{self.base_url}states", headers=self.headers)
               ^^^^^^^^^^^^^^^^^^^^^^^^^^^^^^^^^^^^^^^^^^^^^^^^^^^^^^^^^^^^
  File "/home/airflow/.local/lib/python3.12/site-packages/requests/api.py", line 73, in get
    return request("get", url, params=params, **kwargs)
           ^^^^^^^^^^^^^^^^^^^^^^^^^^^^^^^^^^^^^^^^^^^^
  File "/home/airflow/.local/lib/python3.12/site-packages/requests/api.py", line 59, in request
    return session.request(method=method, url=url, **kwargs)
           ^^^^^^^^^^^^^^^^^^^^^^^^^^^^^^^^^^^^^^^^^^^^^^^^^
  File "/home/airflow/.local/lib/python3.12/site-packages/requests/sessions.py", line 589, in request
    resp = self.send(prep, **send_kwargs)
           ^^^^^^^^^^^^^^^^^^^^^^^^^^^^^^
  File "/home/airflow/.local/lib/python3.12/site-packages/requests/sessions.py", line 703, in send
    r = adapter.send(request, **kwargs)
        ^^^^^^^^^^^^^^^^^^^^^^^^^^^^^^^
  File "/home/airflow/.local/lib/python3.12/site-packages/requests/adapters.py", line 700, in send
    raise ConnectionError(e, request=request)
requests.exceptions.ConnectionError: HTTPConnectionPool(host='192.168.1.110', port=8123): Max retries exceeded with url: /api/states (Caused by NewConnectionError('<urllib3.connection.HTTPConnection object at 0x7fd8210a4620>: Failed to establish a new connection: [Errno 111] Connection refused'))
[2025-02-28T22:05:24.319+0000] {local_task_job_runner.py:266} INFO - Task exited with return code 1
[2025-02-28T22:05:24.342+0000] {taskinstance.py:3901} INFO - 0 downstream tasks scheduled from follow-on schedule check
[2025-02-28T22:05:24.348+0000] {local_task_job_runner.py:245} INFO - ::endgroup::
