[2025-02-28T05:20:16.013+0000] {local_task_job_runner.py:123} INFO - ::group::Pre task execution logs
[2025-02-28T05:20:16.038+0000] {taskinstance.py:2614} INFO - Dependencies all met for dep_context=non-requeueable deps ti=<TaskInstance: etl_postgres_to_parquet.extract_task manual__2025-02-28T05:06:42.315455+00:00 [queued]>
[2025-02-28T05:20:16.050+0000] {taskinstance.py:2614} INFO - Dependencies all met for dep_context=requeueable deps ti=<TaskInstance: etl_postgres_to_parquet.extract_task manual__2025-02-28T05:06:42.315455+00:00 [queued]>
[2025-02-28T05:20:16.052+0000] {taskinstance.py:2867} INFO - Starting attempt 2 of 2
[2025-02-28T05:20:16.092+0000] {taskinstance.py:2890} INFO - Executing <Task(PythonOperator): extract_task> on 2025-02-28 05:06:42.315455+00:00
[2025-02-28T05:20:16.104+0000] {standard_task_runner.py:104} INFO - Running: ['***', 'tasks', 'run', 'etl_postgres_to_parquet', 'extract_task', 'manual__2025-02-28T05:06:42.315455+00:00', '--job-id', '56', '--raw', '--subdir', 'DAGS_FOLDER/etl_process_to_parquet.py', '--cfg-path', '/tmp/tmpb7onzox4']
[2025-02-28T05:20:16.107+0000] {standard_task_runner.py:105} INFO - Job 56: Subtask extract_task
[2025-02-28T05:20:16.111+0000] {logging_mixin.py:190} WARNING - /home/***/.local/lib/python3.12/site-packages/***/task/task_runner/standard_task_runner.py:70 DeprecationWarning: This process (pid=189) is multi-threaded, use of fork() may lead to deadlocks in the child.
[2025-02-28T05:20:16.112+0000] {standard_task_runner.py:72} INFO - Started process 279 to run task
[2025-02-28T05:20:16.171+0000] {task_command.py:467} INFO - Running <TaskInstance: etl_postgres_to_parquet.extract_task manual__2025-02-28T05:06:42.315455+00:00 [running]> on host 151d4861bf1b
[2025-02-28T05:20:16.286+0000] {taskinstance.py:3134} INFO - Exporting env vars: AIRFLOW_CTX_DAG_OWNER='***' AIRFLOW_CTX_DAG_ID='etl_postgres_to_parquet' AIRFLOW_CTX_TASK_ID='extract_task' AIRFLOW_CTX_EXECUTION_DATE='2025-02-28T05:06:42.315455+00:00' AIRFLOW_CTX_TRY_NUMBER='2' AIRFLOW_CTX_DAG_RUN_ID='manual__2025-02-28T05:06:42.315455+00:00'
[2025-02-28T05:20:16.288+0000] {logging_mixin.py:190} INFO - Task instance is in running state
[2025-02-28T05:20:16.289+0000] {logging_mixin.py:190} INFO -  Previous state of the Task instance: queued
[2025-02-28T05:20:16.290+0000] {logging_mixin.py:190} INFO - Current task name:extract_task state:running start_date:2025-02-28 05:20:16.038913+00:00
[2025-02-28T05:20:16.290+0000] {logging_mixin.py:190} INFO - Dag name:etl_postgres_to_parquet and current dag run status:running
[2025-02-28T05:20:16.291+0000] {taskinstance.py:732} INFO - ::endgroup::
[2025-02-28T05:20:16.302+0000] {base.py:84} INFO - Retrieving connection '***_default'
[2025-02-28T05:20:16.304+0000] {taskinstance.py:3313} ERROR - Task failed with exception
Traceback (most recent call last):
  File "/home/airflow/.local/lib/python3.12/site-packages/airflow/models/taskinstance.py", line 768, in _execute_task
    result = _execute_callable(context=context, **execute_callable_kwargs)
             ^^^^^^^^^^^^^^^^^^^^^^^^^^^^^^^^^^^^^^^^^^^^^^^^^^^^^^^^^^^^^
  File "/home/airflow/.local/lib/python3.12/site-packages/airflow/models/taskinstance.py", line 734, in _execute_callable
    return ExecutionCallableRunner(
           ^^^^^^^^^^^^^^^^^^^^^^^^
  File "/home/airflow/.local/lib/python3.12/site-packages/airflow/utils/operator_helpers.py", line 252, in run
    return self.func(*args, **kwargs)
           ^^^^^^^^^^^^^^^^^^^^^^^^^^
  File "/home/airflow/.local/lib/python3.12/site-packages/airflow/models/baseoperator.py", line 424, in wrapper
    return func(self, *args, **kwargs)
           ^^^^^^^^^^^^^^^^^^^^^^^^^^^
  File "/home/airflow/.local/lib/python3.12/site-packages/airflow/operators/python.py", line 238, in execute
    return_value = self.execute_callable()
                   ^^^^^^^^^^^^^^^^^^^^^^^
  File "/home/airflow/.local/lib/python3.12/site-packages/airflow/operators/python.py", line 256, in execute_callable
    return runner.run(*self.op_args, **self.op_kwargs)
           ^^^^^^^^^^^^^^^^^^^^^^^^^^^^^^^^^^^^^^^^^^^
  File "/home/airflow/.local/lib/python3.12/site-packages/airflow/utils/operator_helpers.py", line 252, in run
    return self.func(*args, **kwargs)
           ^^^^^^^^^^^^^^^^^^^^^^^^^^
  File "/opt/airflow/dags/etl_process_to_parquet.py", line 14, in extract_data
    conn = postgres_hook.get_conn()
           ^^^^^^^^^^^^^^^^^^^^^^^^
  File "/home/airflow/.local/lib/python3.12/site-packages/airflow/providers/postgres/hooks/postgres.py", line 165, in get_conn
    self.conn = psycopg2.connect(**conn_args)
                ^^^^^^^^^^^^^^^^^^^^^^^^^^^^^
  File "/home/airflow/.local/lib/python3.12/site-packages/psycopg2/__init__.py", line 122, in connect
    conn = _connect(dsn, connection_factory=connection_factory, **kwasync)
           ^^^^^^^^^^^^^^^^^^^^^^^^^^^^^^^^^^^^^^^^^^^^^^^^^^^^^^^^^^^^^^^
psycopg2.OperationalError: connection to server at "localhost" (::1), port 5432 failed: Connection refused
	Is the server running on that host and accepting TCP/IP connections?
connection to server at "localhost" (127.0.0.1), port 5432 failed: Connection refused
	Is the server running on that host and accepting TCP/IP connections?

[2025-02-28T05:20:16.319+0000] {logging_mixin.py:190} INFO - Task instance in failure state
[2025-02-28T05:20:16.320+0000] {logging_mixin.py:190} INFO - Task start:2025-02-28 05:20:16.038913+00:00 end:2025-02-28 05:20:16.319323+00:00 duration:0.28041
[2025-02-28T05:20:16.321+0000] {logging_mixin.py:190} INFO - Task:<Task(PythonOperator): extract_task> dag:<DAG: etl_***_to_parquet> dagrun:<DagRun etl_***_to_parquet @ 2025-02-28 05:06:42.315455+00:00: manual__2025-02-28T05:06:42.315455+00:00, state:running, queued_at: 2025-02-28 05:06:42.349208+00:00. externally triggered: True>
[2025-02-28T05:20:16.321+0000] {logging_mixin.py:190} INFO - Failure caused by connection to server at "localhost" (::1), port 5432 failed: Connection refused
	Is the server running on that host and accepting TCP/IP connections?
connection to server at "localhost" (127.0.0.1), port 5432 failed: Connection refused
	Is the server running on that host and accepting TCP/IP connections?
[2025-02-28T05:20:16.322+0000] {taskinstance.py:1226} INFO - Marking task as FAILED. dag_id=etl_***_to_parquet, task_id=extract_task, run_id=manual__2025-02-28T05:06:42.315455+00:00, execution_date=20250228T050642, start_date=20250228T052016, end_date=20250228T052016
[2025-02-28T05:20:16.359+0000] {taskinstance.py:341} INFO - ::group::Post task execution logs
[2025-02-28T05:20:16.360+0000] {standard_task_runner.py:124} ERROR - Failed to execute job 56 for task extract_task (connection to server at "localhost" (::1), port 5432 failed: Connection refused
	Is the server running on that host and accepting TCP/IP connections?
connection to server at "localhost" (127.0.0.1), port 5432 failed: Connection refused
	Is the server running on that host and accepting TCP/IP connections?
; 279)
Traceback (most recent call last):
  File "/home/airflow/.local/lib/python3.12/site-packages/airflow/task/task_runner/standard_task_runner.py", line 117, in _start_by_fork
    ret = args.func(args, dag=self.dag)
          ^^^^^^^^^^^^^^^^^^^^^^^^^^^^^
  File "/home/airflow/.local/lib/python3.12/site-packages/airflow/cli/cli_config.py", line 49, in command
    return func(*args, **kwargs)
           ^^^^^^^^^^^^^^^^^^^^^
  File "/home/airflow/.local/lib/python3.12/site-packages/airflow/utils/cli.py", line 116, in wrapper
    return f(*args, **kwargs)
           ^^^^^^^^^^^^^^^^^^
  File "/home/airflow/.local/lib/python3.12/site-packages/airflow/cli/commands/task_command.py", line 483, in task_run
    task_return_code = _run_task_by_selected_method(args, _dag, ti)
                       ^^^^^^^^^^^^^^^^^^^^^^^^^^^^^^^^^^^^^^^^^^^^
  File "/home/airflow/.local/lib/python3.12/site-packages/airflow/cli/commands/task_command.py", line 256, in _run_task_by_selected_method
    return _run_raw_task(args, ti)
           ^^^^^^^^^^^^^^^^^^^^^^^
  File "/home/airflow/.local/lib/python3.12/site-packages/airflow/cli/commands/task_command.py", line 341, in _run_raw_task
    return ti._run_raw_task(
           ^^^^^^^^^^^^^^^^^
  File "/home/airflow/.local/lib/python3.12/site-packages/airflow/utils/session.py", line 97, in wrapper
    return func(*args, session=session, **kwargs)
           ^^^^^^^^^^^^^^^^^^^^^^^^^^^^^^^^^^^^^^
  File "/home/airflow/.local/lib/python3.12/site-packages/airflow/models/taskinstance.py", line 3006, in _run_raw_task
    return _run_raw_task(
           ^^^^^^^^^^^^^^
  File "/home/airflow/.local/lib/python3.12/site-packages/airflow/models/taskinstance.py", line 274, in _run_raw_task
    TaskInstance._execute_task_with_callbacks(
  File "/home/airflow/.local/lib/python3.12/site-packages/airflow/models/taskinstance.py", line 3161, in _execute_task_with_callbacks
    result = self._execute_task(context, task_orig)
             ^^^^^^^^^^^^^^^^^^^^^^^^^^^^^^^^^^^^^^
  File "/home/airflow/.local/lib/python3.12/site-packages/airflow/models/taskinstance.py", line 3185, in _execute_task
    return _execute_task(self, context, task_orig)
           ^^^^^^^^^^^^^^^^^^^^^^^^^^^^^^^^^^^^^^^
  File "/home/airflow/.local/lib/python3.12/site-packages/airflow/models/taskinstance.py", line 768, in _execute_task
    result = _execute_callable(context=context, **execute_callable_kwargs)
             ^^^^^^^^^^^^^^^^^^^^^^^^^^^^^^^^^^^^^^^^^^^^^^^^^^^^^^^^^^^^^
  File "/home/airflow/.local/lib/python3.12/site-packages/airflow/models/taskinstance.py", line 734, in _execute_callable
    return ExecutionCallableRunner(
           ^^^^^^^^^^^^^^^^^^^^^^^^
  File "/home/airflow/.local/lib/python3.12/site-packages/airflow/utils/operator_helpers.py", line 252, in run
    return self.func(*args, **kwargs)
           ^^^^^^^^^^^^^^^^^^^^^^^^^^
  File "/home/airflow/.local/lib/python3.12/site-packages/airflow/models/baseoperator.py", line 424, in wrapper
    return func(self, *args, **kwargs)
           ^^^^^^^^^^^^^^^^^^^^^^^^^^^
  File "/home/airflow/.local/lib/python3.12/site-packages/airflow/operators/python.py", line 238, in execute
    return_value = self.execute_callable()
                   ^^^^^^^^^^^^^^^^^^^^^^^
  File "/home/airflow/.local/lib/python3.12/site-packages/airflow/operators/python.py", line 256, in execute_callable
    return runner.run(*self.op_args, **self.op_kwargs)
           ^^^^^^^^^^^^^^^^^^^^^^^^^^^^^^^^^^^^^^^^^^^
  File "/home/airflow/.local/lib/python3.12/site-packages/airflow/utils/operator_helpers.py", line 252, in run
    return self.func(*args, **kwargs)
           ^^^^^^^^^^^^^^^^^^^^^^^^^^
  File "/opt/airflow/dags/etl_process_to_parquet.py", line 14, in extract_data
    conn = postgres_hook.get_conn()
           ^^^^^^^^^^^^^^^^^^^^^^^^
  File "/home/airflow/.local/lib/python3.12/site-packages/airflow/providers/postgres/hooks/postgres.py", line 165, in get_conn
    self.conn = psycopg2.connect(**conn_args)
                ^^^^^^^^^^^^^^^^^^^^^^^^^^^^^
  File "/home/airflow/.local/lib/python3.12/site-packages/psycopg2/__init__.py", line 122, in connect
    conn = _connect(dsn, connection_factory=connection_factory, **kwasync)
           ^^^^^^^^^^^^^^^^^^^^^^^^^^^^^^^^^^^^^^^^^^^^^^^^^^^^^^^^^^^^^^^
psycopg2.OperationalError: connection to server at "localhost" (::1), port 5432 failed: Connection refused
	Is the server running on that host and accepting TCP/IP connections?
connection to server at "localhost" (127.0.0.1), port 5432 failed: Connection refused
	Is the server running on that host and accepting TCP/IP connections?

[2025-02-28T05:20:16.409+0000] {local_task_job_runner.py:266} INFO - Task exited with return code 1
[2025-02-28T05:20:16.422+0000] {local_task_job_runner.py:245} INFO - ::endgroup::
