[2025-02-28T21:55:07.543+0000] {local_task_job_runner.py:123} INFO - ::group::Pre task execution logs
[2025-02-28T21:55:07.564+0000] {taskinstance.py:2614} INFO - Dependencies all met for dep_context=non-requeueable deps ti=<TaskInstance: ha_etl_process.extract_task manual__2025-02-28T21:55:05.573386+00:00 [queued]>
[2025-02-28T21:55:07.572+0000] {taskinstance.py:2614} INFO - Dependencies all met for dep_context=requeueable deps ti=<TaskInstance: ha_etl_process.extract_task manual__2025-02-28T21:55:05.573386+00:00 [queued]>
[2025-02-28T21:55:07.573+0000] {taskinstance.py:2867} INFO - Starting attempt 1 of 2
[2025-02-28T21:55:07.593+0000] {taskinstance.py:2890} INFO - Executing <Task(PythonOperator): extract_task> on 2025-02-28 21:55:05.573386+00:00
[2025-02-28T21:55:07.611+0000] {standard_task_runner.py:104} INFO - Running: ['***', 'tasks', 'run', 'ha_etl_process', 'extract_task', 'manual__2025-02-28T21:55:05.573386+00:00', '--job-id', '137', '--raw', '--subdir', 'DAGS_FOLDER/ha_etl_process.py', '--cfg-path', '/tmp/tmpvf21y312']
[2025-02-28T21:55:07.614+0000] {standard_task_runner.py:105} INFO - Job 137: Subtask extract_task
[2025-02-28T21:55:07.619+0000] {logging_mixin.py:190} WARNING - /home/***/.local/lib/python3.12/site-packages/***/task/task_runner/standard_task_runner.py:70 DeprecationWarning: This process (pid=801) is multi-threaded, use of fork() may lead to deadlocks in the child.
[2025-02-28T21:55:07.620+0000] {standard_task_runner.py:72} INFO - Started process 802 to run task
[2025-02-28T21:55:07.670+0000] {task_command.py:467} INFO - Running <TaskInstance: ha_etl_process.extract_task manual__2025-02-28T21:55:05.573386+00:00 [running]> on host 151d4861bf1b
[2025-02-28T21:55:07.772+0000] {taskinstance.py:3134} INFO - Exporting env vars: AIRFLOW_CTX_DAG_OWNER='***' AIRFLOW_CTX_DAG_ID='ha_etl_process' AIRFLOW_CTX_TASK_ID='extract_task' AIRFLOW_CTX_EXECUTION_DATE='2025-02-28T21:55:05.573386+00:00' AIRFLOW_CTX_TRY_NUMBER='1' AIRFLOW_CTX_DAG_RUN_ID='manual__2025-02-28T21:55:05.573386+00:00'
[2025-02-28T21:55:07.774+0000] {logging_mixin.py:190} INFO - Task instance is in running state
[2025-02-28T21:55:07.775+0000] {logging_mixin.py:190} INFO -  Previous state of the Task instance: queued
[2025-02-28T21:55:07.776+0000] {logging_mixin.py:190} INFO - Current task name:extract_task state:running start_date:2025-02-28 21:55:07.565168+00:00
[2025-02-28T21:55:07.776+0000] {logging_mixin.py:190} INFO - Dag name:ha_etl_process and current dag run status:running
[2025-02-28T21:55:07.777+0000] {taskinstance.py:732} INFO - ::endgroup::
[2025-02-28T21:55:07.779+0000] {logging_mixin.py:190} INFO - üîç Tentando se conectar ao Home Assistant...
[2025-02-28T21:55:07.780+0000] {logging_mixin.py:190} INFO - 
Testing API connection...
[2025-02-28T21:55:07.780+0000] {logging_mixin.py:190} INFO - Error: 'HomeAssistantAPI' object has no attribute 'get_states'
[2025-02-28T21:55:07.781+0000] {logging_mixin.py:190} INFO - <unusual_prefix_8f7033247fce1c2ce5759715b0045e7a21193f9c_ha_etl_process.HomeAssistantAPI object at 0x7ff94b873dd0>
[2025-02-28T21:55:07.781+0000] {logging_mixin.py:190} INFO - ‚ùå Erro na extra√ß√£o dos dados: 'HomeAssistantAPI' object has no attribute 'get_states'
[2025-02-28T21:55:07.782+0000] {taskinstance.py:3313} ERROR - Task failed with exception
Traceback (most recent call last):
  File "/home/airflow/.local/lib/python3.12/site-packages/airflow/models/taskinstance.py", line 768, in _execute_task
    result = _execute_callable(context=context, **execute_callable_kwargs)
             ^^^^^^^^^^^^^^^^^^^^^^^^^^^^^^^^^^^^^^^^^^^^^^^^^^^^^^^^^^^^^
  File "/home/airflow/.local/lib/python3.12/site-packages/airflow/models/taskinstance.py", line 734, in _execute_callable
    return ExecutionCallableRunner(
           ^^^^^^^^^^^^^^^^^^^^^^^^
  File "/home/airflow/.local/lib/python3.12/site-packages/airflow/utils/operator_helpers.py", line 252, in run
    return self.func(*args, **kwargs)
           ^^^^^^^^^^^^^^^^^^^^^^^^^^
  File "/home/airflow/.local/lib/python3.12/site-packages/airflow/models/baseoperator.py", line 424, in wrapper
    return func(self, *args, **kwargs)
           ^^^^^^^^^^^^^^^^^^^^^^^^^^^
  File "/home/airflow/.local/lib/python3.12/site-packages/airflow/operators/python.py", line 238, in execute
    return_value = self.execute_callable()
                   ^^^^^^^^^^^^^^^^^^^^^^^
  File "/home/airflow/.local/lib/python3.12/site-packages/airflow/operators/python.py", line 256, in execute_callable
    return runner.run(*self.op_args, **self.op_kwargs)
           ^^^^^^^^^^^^^^^^^^^^^^^^^^^^^^^^^^^^^^^^^^^
  File "/home/airflow/.local/lib/python3.12/site-packages/airflow/utils/operator_helpers.py", line 252, in run
    return self.func(*args, **kwargs)
           ^^^^^^^^^^^^^^^^^^^^^^^^^^
  File "/opt/airflow/dags/ha_etl_process.py", line 110, in extract_data
    all_states = ha.get_states()
                 ^^^^^^^^^^^^^
AttributeError: 'HomeAssistantAPI' object has no attribute 'get_states'
[2025-02-28T21:55:07.804+0000] {logging_mixin.py:190} INFO - Task instance in failure state
[2025-02-28T21:55:07.805+0000] {logging_mixin.py:190} INFO - Task start:2025-02-28 21:55:07.565168+00:00 end:2025-02-28 21:55:07.803903+00:00 duration:0.238735
[2025-02-28T21:55:07.805+0000] {logging_mixin.py:190} INFO - Task:<Task(PythonOperator): extract_task> dag:<DAG: ha_etl_process> dagrun:<DagRun ha_etl_process @ 2025-02-28 21:55:05.573386+00:00: manual__2025-02-28T21:55:05.573386+00:00, state:running, queued_at: 2025-02-28 21:55:05.591690+00:00. externally triggered: True>
[2025-02-28T21:55:07.806+0000] {logging_mixin.py:190} INFO - Failure caused by 'HomeAssistantAPI' object has no attribute 'get_states'
[2025-02-28T21:55:07.807+0000] {taskinstance.py:1226} INFO - Marking task as UP_FOR_RETRY. dag_id=ha_etl_process, task_id=extract_task, run_id=manual__2025-02-28T21:55:05.573386+00:00, execution_date=20250228T215505, start_date=20250228T215507, end_date=20250228T215507
[2025-02-28T21:55:07.848+0000] {taskinstance.py:341} INFO - ::group::Post task execution logs
[2025-02-28T21:55:07.849+0000] {standard_task_runner.py:124} ERROR - Failed to execute job 137 for task extract_task ('HomeAssistantAPI' object has no attribute 'get_states'; 802)
Traceback (most recent call last):
  File "/home/airflow/.local/lib/python3.12/site-packages/airflow/task/task_runner/standard_task_runner.py", line 117, in _start_by_fork
    ret = args.func(args, dag=self.dag)
          ^^^^^^^^^^^^^^^^^^^^^^^^^^^^^
  File "/home/airflow/.local/lib/python3.12/site-packages/airflow/cli/cli_config.py", line 49, in command
    return func(*args, **kwargs)
           ^^^^^^^^^^^^^^^^^^^^^
  File "/home/airflow/.local/lib/python3.12/site-packages/airflow/utils/cli.py", line 116, in wrapper
    return f(*args, **kwargs)
           ^^^^^^^^^^^^^^^^^^
  File "/home/airflow/.local/lib/python3.12/site-packages/airflow/cli/commands/task_command.py", line 483, in task_run
    task_return_code = _run_task_by_selected_method(args, _dag, ti)
                       ^^^^^^^^^^^^^^^^^^^^^^^^^^^^^^^^^^^^^^^^^^^^
  File "/home/airflow/.local/lib/python3.12/site-packages/airflow/cli/commands/task_command.py", line 256, in _run_task_by_selected_method
    return _run_raw_task(args, ti)
           ^^^^^^^^^^^^^^^^^^^^^^^
  File "/home/airflow/.local/lib/python3.12/site-packages/airflow/cli/commands/task_command.py", line 341, in _run_raw_task
    return ti._run_raw_task(
           ^^^^^^^^^^^^^^^^^
  File "/home/airflow/.local/lib/python3.12/site-packages/airflow/utils/session.py", line 97, in wrapper
    return func(*args, session=session, **kwargs)
           ^^^^^^^^^^^^^^^^^^^^^^^^^^^^^^^^^^^^^^
  File "/home/airflow/.local/lib/python3.12/site-packages/airflow/models/taskinstance.py", line 3006, in _run_raw_task
    return _run_raw_task(
           ^^^^^^^^^^^^^^
  File "/home/airflow/.local/lib/python3.12/site-packages/airflow/models/taskinstance.py", line 274, in _run_raw_task
    TaskInstance._execute_task_with_callbacks(
  File "/home/airflow/.local/lib/python3.12/site-packages/airflow/models/taskinstance.py", line 3161, in _execute_task_with_callbacks
    result = self._execute_task(context, task_orig)
             ^^^^^^^^^^^^^^^^^^^^^^^^^^^^^^^^^^^^^^
  File "/home/airflow/.local/lib/python3.12/site-packages/airflow/models/taskinstance.py", line 3185, in _execute_task
    return _execute_task(self, context, task_orig)
           ^^^^^^^^^^^^^^^^^^^^^^^^^^^^^^^^^^^^^^^
  File "/home/airflow/.local/lib/python3.12/site-packages/airflow/models/taskinstance.py", line 768, in _execute_task
    result = _execute_callable(context=context, **execute_callable_kwargs)
             ^^^^^^^^^^^^^^^^^^^^^^^^^^^^^^^^^^^^^^^^^^^^^^^^^^^^^^^^^^^^^
  File "/home/airflow/.local/lib/python3.12/site-packages/airflow/models/taskinstance.py", line 734, in _execute_callable
    return ExecutionCallableRunner(
           ^^^^^^^^^^^^^^^^^^^^^^^^
  File "/home/airflow/.local/lib/python3.12/site-packages/airflow/utils/operator_helpers.py", line 252, in run
    return self.func(*args, **kwargs)
           ^^^^^^^^^^^^^^^^^^^^^^^^^^
  File "/home/airflow/.local/lib/python3.12/site-packages/airflow/models/baseoperator.py", line 424, in wrapper
    return func(self, *args, **kwargs)
           ^^^^^^^^^^^^^^^^^^^^^^^^^^^
  File "/home/airflow/.local/lib/python3.12/site-packages/airflow/operators/python.py", line 238, in execute
    return_value = self.execute_callable()
                   ^^^^^^^^^^^^^^^^^^^^^^^
  File "/home/airflow/.local/lib/python3.12/site-packages/airflow/operators/python.py", line 256, in execute_callable
    return runner.run(*self.op_args, **self.op_kwargs)
           ^^^^^^^^^^^^^^^^^^^^^^^^^^^^^^^^^^^^^^^^^^^
  File "/home/airflow/.local/lib/python3.12/site-packages/airflow/utils/operator_helpers.py", line 252, in run
    return self.func(*args, **kwargs)
           ^^^^^^^^^^^^^^^^^^^^^^^^^^
  File "/opt/airflow/dags/ha_etl_process.py", line 110, in extract_data
    all_states = ha.get_states()
                 ^^^^^^^^^^^^^
AttributeError: 'HomeAssistantAPI' object has no attribute 'get_states'
[2025-02-28T21:55:07.877+0000] {local_task_job_runner.py:266} INFO - Task exited with return code 1
[2025-02-28T21:55:07.907+0000] {taskinstance.py:3901} INFO - 0 downstream tasks scheduled from follow-on schedule check
[2025-02-28T21:55:07.914+0000] {local_task_job_runner.py:245} INFO - ::endgroup::
